{
    DataVersion: 3465,
    size: [80, 130, 72],
    data: [
        {pos: [0, 0, 0], state: "minecraft:dirt"},
        {pos: [55, 8, 26], state: "minecraft:water{level:8}"},
        {pos: [56, 8, 27], state: "minecraft:water{level:8}"},
        {pos: [57, 8, 27], state: "minecraft:water{level:8}"},
        {pos: [58, 8, 28], state: "minecraft:water{level:8}"},
        {pos: [55, 9, 26], state: "minecraft:water{level:8}"},
        {pos: [56, 9, 27], state: "minecraft:water{level:8}"},
        {pos: [57, 9, 27], state: "minecraft:water{level:8}"},
        {pos: [58, 9, 28], state: "minecraft:water{level:8}"},
        {pos: [55, 10, 26], state: "minecraft:water{level:8}"},
        {pos: [56, 10, 27], state: "minecraft:water{level:8}"},
        {pos: [57, 10, 27], state: "minecraft:water{level:8}"},
        {pos: [58, 10, 28], state: "minecraft:water{level:8}"},
        {pos: [55, 11, 26], state: "minecraft:water{level:8}"},
        {pos: [56, 11, 27], state: "minecraft:water{level:8}"},
        {pos: [57, 11, 27], state: "minecraft:water{level:8}"},
        {pos: [58, 11, 28], state: "minecraft:water{level:8}"},
        {pos: [55, 12, 26], state: "minecraft:water{level:8}"},
        {pos: [56, 12, 27], state: "minecraft:water{level:8}"},
        {pos: [57, 12, 27], state: "minecraft:water{level:8}"},
        {pos: [58, 12, 28], state: "minecraft:water{level:8}"},
        {pos: [55, 13, 26], state: "minecraft:water{level:8}"},
        {pos: [56, 13, 27], state: "minecraft:water{level:8}"},
        {pos: [57, 13, 27], state: "minecraft:water{level:8}"},
        {pos: [58, 13, 28], state: "minecraft:water{level:8}"},
        {pos: [55, 14, 26], state: "minecraft:water{level:8}"},
        {pos: [56, 14, 27], state: "minecraft:water{level:8}"},
        {pos: [57, 14, 27], state: "minecraft:water{level:8}"},
        {pos: [58, 14, 28], state: "minecraft:water{level:8}"},
        {pos: [55, 15, 26], state: "minecraft:water{level:8}"},
        {pos: [56, 15, 27], state: "minecraft:water{level:8}"},
        {pos: [57, 15, 27], state: "minecraft:water{level:8}"},
        {pos: [58, 15, 28], state: "minecraft:water{level:8}"},
        {pos: [55, 16, 26], state: "minecraft:water{level:8}"},
        {pos: [56, 16, 27], state: "minecraft:water{level:8}"},
        {pos: [57, 16, 27], state: "minecraft:water{level:8}"},
        {pos: [58, 16, 28], state: "minecraft:water{level:8}"},
        {pos: [55, 17, 26], state: "minecraft:water{level:8}"},
        {pos: [56, 17, 27], state: "minecraft:water{level:8}"},
        {pos: [57, 17, 27], state: "minecraft:water{level:8}"},
        {pos: [58, 17, 28], state: "minecraft:water{level:8}"},
        {pos: [55, 18, 26], state: "minecraft:water{level:8}"},
        {pos: [56, 18, 27], state: "minecraft:water{level:8}"},
        {pos: [57, 18, 27], state: "minecraft:water{level:8}"},
        {pos: [58, 18, 28], state: "minecraft:water{level:8}"},
        {pos: [55, 19, 26], state: "minecraft:water{level:8}"},
        {pos: [56, 19, 27], state: "minecraft:water{level:8}"},
        {pos: [57, 19, 27], state: "minecraft:water{level:8}"},
        {pos: [58, 19, 28], state: "minecraft:water{level:8}"},
        {pos: [55, 20, 26], state: "minecraft:water{level:8}"},
        {pos: [56, 20, 27], state: "minecraft:water{level:8}"},
        {pos: [57, 20, 27], state: "minecraft:water{level:8}"},
        {pos: [58, 20, 28], state: "minecraft:water{level:8}"},
        {pos: [55, 21, 26], state: "minecraft:water{level:8}"},
        {pos: [56, 21, 27], state: "minecraft:water{level:8}"},
        {pos: [57, 21, 27], state: "minecraft:water{level:8}"},
        {pos: [58, 21, 28], state: "minecraft:water{level:8}"},
        {pos: [55, 22, 26], state: "minecraft:water{level:8}"},
        {pos: [56, 22, 27], state: "minecraft:water{level:8}"},
        {pos: [57, 22, 27], state: "minecraft:water{level:8}"},
        {pos: [58, 22, 28], state: "minecraft:water{level:8}"},
        {pos: [63, 22, 52], state: "minecraft:stone"},
        {pos: [55, 23, 26], state: "minecraft:water{level:8}"},
        {pos: [56, 23, 27], state: "minecraft:water{level:8}"},
        {pos: [57, 23, 27], state: "minecraft:water{level:8}"},
        {pos: [58, 23, 28], state: "minecraft:water{level:8}"},
        {pos: [63, 23, 52], state: "minecraft:stone"},
        {pos: [55, 24, 26], state: "minecraft:water{level:8}"},
        {pos: [56, 24, 27], state: "minecraft:water{level:8}"},
        {pos: [57, 24, 27], state: "minecraft:water{level:8}"},
        {pos: [58, 24, 28], state: "minecraft:water{level:8}"},
        {pos: [63, 24, 52], state: "minecraft:stone"},
        {pos: [63, 24, 53], state: "minecraft:cyan_terracotta"},
        {pos: [64, 24, 52], state: "minecraft:stone"},
        {pos: [52, 25, 34], state: "minecraft:stone"},
        {pos: [55, 25, 26], state: "minecraft:water{level:8}"},
        {pos: [56, 25, 27], state: "minecraft:water{level:8}"},
        {pos: [57, 25, 27], state: "minecraft:water{level:8}"},
        {pos: [58, 25, 28], state: "minecraft:water{level:8}"},
        {pos: [62, 25, 53], state: "minecraft:cyan_terracotta"},
        {pos: [63, 25, 51], state: "minecraft:stone"},
        {pos: [63, 25, 52], state: "minecraft:stone"},
        {pos: [63, 25, 53], state: "minecraft:stone"},
        {pos: [64, 25, 52], state: "minecraft:cyan_terracotta"},
        {pos: [52, 26, 34], state: "minecraft:stone"},
        {pos: [55, 26, 26], state: "minecraft:water{level:8}"},
        {pos: [56, 26, 27], state: "minecraft:water{level:8}"},
        {pos: [57, 26, 27], state: "minecraft:water{level:8}"},
        {pos: [58, 26, 28], state: "minecraft:water{level:8}"},
        {pos: [62, 26, 52], state: "minecraft:cyan_terracotta"},
        {pos: [62, 26, 53], state: "minecraft:stone"},
        {pos: [63, 26, 51], state: "minecraft:stone"},
        {pos: [63, 26, 52], state: "minecraft:cyan_terracotta"},
        {pos: [63, 26, 53], state: "minecraft:stone"},
        {pos: [64, 26, 51], state: "minecraft:stone"},
        {pos: [64, 26, 52], state: "minecraft:stone"},
        {pos: [39, 27, 50], state: "minecraft:stone"},
        {pos: [52, 27, 34], state: "minecraft:cyan_terracotta"},
        {pos: [55, 27, 26], state: "minecraft:water{level:8}"},
        {pos: [56, 27, 27], state: "minecraft:water{level:8}"},
        {pos: [57, 27, 27], state: "minecraft:water{level:8}"},
        {pos: [58, 27, 28], state: "minecraft:water{level:8}"},
        {pos: [62, 27, 51], state: "minecraft:stone"},
        {pos: [62, 27, 52], state: "minecraft:cyan_terracotta"},
        {pos: [62, 27, 53], state: "minecraft:cyan_terracotta"},
        {pos: [63, 27, 51], state: "minecraft:stone"},
        {pos: [63, 27, 52], state: "minecraft:stone"},
        {pos: [63, 27, 53], state: "minecraft:stone"},
        {pos: [64, 27, 51], state: "minecraft:stone"},
        {pos: [64, 27, 52], state: "minecraft:stone"},
        {pos: [64, 27, 53], state: "minecraft:cyan_terracotta"},
        {pos: [39, 28, 50], state: "minecraft:stone"},
        {pos: [51, 28, 34], state: "minecraft:stone"},
        {pos: [52, 28, 33], state: "minecraft:stone"},
        {pos: [52, 28, 34], state: "minecraft:stone"},
        {pos: [55, 28, 26], state: "minecraft:water{level:8}"},
        {pos: [56, 28, 27], state: "minecraft:water{level:8}"},
        {pos: [57, 28, 27], state: "minecraft:water{level:8}"},
        {pos: [58, 28, 28], state: "minecraft:water{level:8}"},
        {pos: [62, 28, 51], state: "minecraft:cyan_terracotta"},
        {pos: [62, 28, 52], state: "minecraft:stone"},
        {pos: [62, 28, 53], state: "minecraft:cyan_terracotta"},
        {pos: [63, 28, 51], state: "minecraft:stone"},
        {pos: [63, 28, 52], state: "minecraft:cyan_terracotta"},
        {pos: [63, 28, 53], state: "minecraft:cyan_terracotta"},
        {pos: [64, 28, 51], state: "minecraft:stone"},
        {pos: [64, 28, 52], state: "minecraft:stone"},
        {pos: [64, 28, 53], state: "minecraft:stone"},
        {pos: [35, 29, 35], state: "minecraft:bedrock"},
        {pos: [38, 29, 50], state: "minecraft:stone"},
        {pos: [39, 29, 49], state: "minecraft:stone"},
        {pos: [39, 29, 50], state: "minecraft:cyan_terracotta"},
        {pos: [39, 29, 51], state: "minecraft:stone"},
        {pos: [40, 29, 49], state: "minecraft:cyan_terracotta"},
        {pos: [51, 29, 33], state: "minecraft:stone"},
        {pos: [51, 29, 34], state: "minecraft:cyan_terracotta"},
        {pos: [51, 29, 35], state: "minecraft:stone"},
        {pos: [52, 29, 33], state: "minecraft:stone"},
        {pos: [52, 29, 34], state: "minecraft:cyan_terracotta"},
        {pos: [52, 29, 35], state: "minecraft:stone"},
        {pos: [53, 29, 34], state: "minecraft:cyan_terracotta"},
        {pos: [55, 29, 26], state: "minecraft:water{level:8}"},
        {pos: [56, 29, 27], state: "minecraft:water{level:8}"},
        {pos: [57, 29, 27], state: "minecraft:water{level:8}"},
        {pos: [58, 29, 28], state: "minecraft:water{level:8}"},
        {pos: [62, 29, 51], state: "minecraft:stone"},
        {pos: [62, 29, 52], state: "minecraft:stone"},
        {pos: [62, 29, 53], state: "minecraft:cyan_terracotta"},
        {pos: [63, 29, 51], state: "minecraft:stone"},
        {pos: [63, 29, 52], state: "minecraft:stone"},
        {pos: [63, 29, 53], state: "minecraft:stone"},
        {pos: [63, 29, 54], state: "minecraft:stone"},
        {pos: [64, 29, 51], state: "minecraft:stone"},
        {pos: [64, 29, 52], state: "minecraft:cyan_terracotta"},
        {pos: [64, 29, 53], state: "minecraft:cyan_terracotta"},
        {pos: [35, 30, 35], state: "minecraft:cyan_terracotta"},
        {pos: [38, 30, 50], state: "minecraft:stone"},
        {pos: [39, 30, 49], state: "minecraft:stone"},
        {pos: [39, 30, 50], state: "minecraft:stone"},
        {pos: [39, 30, 51], state: "minecraft:cyan_terracotta"},
        {pos: [40, 30, 49], state: "minecraft:stone"},
        {pos: [40, 30, 50], state: "minecraft:cyan_terracotta"},
        {pos: [41, 30, 49], state: "minecraft:stone"},
        {pos: [51, 30, 33], state: "minecraft:cyan_terracotta"},
        {pos: [51, 30, 34], state: "minecraft:stone"},
        {pos: [51, 30, 35], state: "minecraft:cyan_terracotta"},
        {pos: [52, 30, 33], state: "minecraft:stone"},
        {pos: [52, 30, 34], state: "minecraft:stone"},
        {pos: [52, 30, 35], state: "minecraft:cyan_terracotta"},
        {pos: [53, 30, 33], state: "minecraft:stone"},
        {pos: [53, 30, 34], state: "minecraft:cyan_terracotta"},
        {pos: [55, 30, 26], state: "minecraft:water{level:8}"},
        {pos: [56, 30, 27], state: "minecraft:water{level:8}"},
        {pos: [57, 30, 27], state: "minecraft:water{level:8}"},
        {pos: [58, 30, 28], state: "minecraft:water{level:8}"},
        {pos: [62, 30, 51], state: "minecraft:stone"},
        {pos: [62, 30, 52], state: "minecraft:cyan_terracotta"},
        {pos: [62, 30, 53], state: "minecraft:stone"},
        {pos: [62, 30, 54], state: "minecraft:stone"},
        {pos: [63, 30, 50], state: "minecraft:cyan_terracotta"},
        {pos: [63, 30, 51], state: "minecraft:cyan_terracotta"},
        {pos: [63, 30, 52], state: "minecraft:cyan_terracotta"},
        {pos: [63, 30, 53], state: "minecraft:stone"},
        {pos: [63, 30, 54], state: "minecraft:stone"},
        {pos: [64, 30, 51], state: "minecraft:stone"},
        {pos: [64, 30, 52], state: "minecraft:stone"},
        {pos: [64, 30, 53], state: "minecraft:cyan_terracotta"},
        {pos: [35, 31, 35], state: "minecraft:cyan_terracotta"},
        {pos: [38, 31, 49], state: "minecraft:stone"},
        {pos: [38, 31, 50], state: "minecraft:cyan_terracotta"},
        {pos: [39, 31, 49], state: "minecraft:stone"},
        {pos: [39, 31, 50], state: "minecraft:stone"},
        {pos: [39, 31, 51], state: "minecraft:stone"},
        {pos: [40, 31, 49], state: "minecraft:cyan_terracotta"},
        {pos: [40, 31, 50], state: "minecraft:stone"},
        {pos: [40, 31, 51], state: "minecraft:cyan_terracotta"},
        {pos: [41, 31, 48], state: "minecraft:cyan_terracotta"},
        {pos: [41, 31, 49], state: "minecraft:stone"},
        {pos: [50, 31, 35], state: "minecraft:stone"},
        {pos: [51, 31, 33], state: "minecraft:cyan_terracotta"},
        {pos: [51, 31, 34], state: "minecraft:cyan_terracotta"},
        {pos: [51, 31, 35], state: "minecraft:cyan_terracotta"},
        {pos: [52, 31, 33], state: "minecraft:cyan_terracotta"},
        {pos: [52, 31, 34], state: "minecraft:cyan_terracotta"},
        {pos: [52, 31, 35], state: "minecraft:stone"},
        {pos: [52, 31, 54], state: "minecraft:stone"},
        {pos: [53, 31, 33], state: "minecraft:stone"},
        {pos: [53, 31, 34], state: "minecraft:cyan_terracotta"},
        {pos: [53, 31, 35], state: "minecraft:stone"},
        {pos: [55, 31, 26], state: "minecraft:water{level:8}"},
        {pos: [56, 31, 27], state: "minecraft:water{level:8}"},
        {pos: [57, 31, 27], state: "minecraft:water{level:8}"},
        {pos: [58, 31, 28], state: "minecraft:water{level:8}"},
        {pos: [62, 31, 51], state: "minecraft:stone"},
        {pos: [62, 31, 52], state: "minecraft:cyan_terracotta"},
        {pos: [62, 31, 53], state: "minecraft:stone"},
        {pos: [62, 31, 54], state: "minecraft:cyan_terracotta"},
        {pos: [63, 31, 50], state: "minecraft:cyan_terracotta"},
        {pos: [63, 31, 51], state: "minecraft:stone"},
        {pos: [63, 31, 52], state: "minecraft:cyan_terracotta"},
        {pos: [63, 31, 53], state: "minecraft:cyan_terracotta"},
        {pos: [63, 31, 54], state: "minecraft:cyan_terracotta"},
        {pos: [64, 31, 50], state: "minecraft:stone"},
        {pos: [64, 31, 51], state: "minecraft:cyan_terracotta"},
        {pos: [64, 31, 52], state: "minecraft:stone"},
        {pos: [64, 31, 53], state: "minecraft:cyan_terracotta"},
        {pos: [65, 31, 52], state: "minecraft:stone"},
        {pos: [34, 32, 35], state: "minecraft:cyan_terracotta"},
        {pos: [34, 32, 36], state: "minecraft:cyan_terracotta"},
        {pos: [35, 32, 34], state: "minecraft:stone"},
        {pos: [35, 32, 35], state: "minecraft:cyan_terracotta"},
        {pos: [36, 32, 34], state: "minecraft:cyan_terracotta"},
        {pos: [36, 32, 35], state: "minecraft:stone"},
        {pos: [38, 32, 49], state: "minecraft:stone"},
        {pos: [38, 32, 50], state: "minecraft:stone"},
        {pos: [38, 32, 51], state: "minecraft:cyan_terracotta"},
        {pos: [39, 32, 49], state: "minecraft:cyan_terracotta"},
        {pos: [39, 32, 50], state: "minecraft:stone"},
        {pos: [39, 32, 51], state: "minecraft:cyan_terracotta"},
        {pos: [40, 32, 48], state: "minecraft:cyan_terracotta"},
        {pos: [40, 32, 49], state: "minecraft:cyan_terracotta"},
        {pos: [40, 32, 50], state: "minecraft:cyan_terracotta"},
        {pos: [40, 32, 51], state: "minecraft:stone"},
        {pos: [41, 32, 48], state: "minecraft:cyan_terracotta"},
        {pos: [41, 32, 49], state: "minecraft:stone"},
        {pos: [41, 32, 50], state: "minecraft:stone"},
        {pos: [50, 32, 35], state: "minecraft:stone"},
        {pos: [51, 32, 33], state: "minecraft:cyan_terracotta"},
        {pos: [51, 32, 34], state: "minecraft:cyan_terracotta"},
        {pos: [51, 32, 35], state: "minecraft:cyan_terracotta"},
        {pos: [51, 32, 36], state: "minecraft:cyan_terracotta"},
        {pos: [52, 32, 32], state: "minecraft:cyan_terracotta"},
        {pos: [52, 32, 33], state: "minecraft:stone"},
        {pos: [52, 32, 34], state: "minecraft:stone"},
        {pos: [52, 32, 35], state: "minecraft:stone"},
        {pos: [52, 32, 36], state: "minecraft:stone"},
        {pos: [52, 32, 54], state: "minecraft:stone"},
        {pos: [53, 32, 33], state: "minecraft:cyan_terracotta"},
        {pos: [53, 32, 34], state: "minecraft:stone"},
        {pos: [53, 32, 35], state: "minecraft:stone"},
        {pos: [55, 32, 26], state: "minecraft:water{level:8}"},
        {pos: [56, 32, 27], state: "minecraft:water{level:8}"},
        {pos: [57, 32, 27], state: "minecraft:water{level:8}"},
        {pos: [58, 32, 28], state: "minecraft:water{level:8}"},
        {pos: [61, 32, 52], state: "minecraft:stone"},
        {pos: [62, 32, 51], state: "minecraft:cyan_terracotta"},
        {pos: [62, 32, 52], state: "minecraft:stone"},
        {pos: [62, 32, 53], state: "minecraft:cyan_terracotta"},
        {pos: [62, 32, 54], state: "minecraft:cyan_terracotta"},
        {pos: [63, 32, 50], state: "minecraft:cyan_terracotta"},
        {pos: [63, 32, 51], state: "minecraft:stone"},
        {pos: [63, 32, 52], state: "minecraft:cyan_terracotta"},
        {pos: [63, 32, 53], state: "minecraft:cyan_terracotta"},
        {pos: [63, 32, 54], state: "minecraft:stone"},
        {pos: [64, 32, 50], state: "minecraft:stone"},
        {pos: [64, 32, 51], state: "minecraft:stone"},
        {pos: [64, 32, 52], state: "minecraft:stone"},
        {pos: [64, 32, 53], state: "minecraft:cyan_terracotta"},
        {pos: [64, 32, 54], state: "minecraft:cyan_terracotta"},
        {pos: [65, 32, 51], state: "minecraft:stone"},
        {pos: [65, 32, 52], state: "minecraft:stone"},
        {pos: [34, 33, 34], state: "minecraft:cyan_terracotta"},
        {pos: [34, 33, 35], state: "minecraft:stone"},
        {pos: [34, 33, 36], state: "minecraft:stone"},
        {pos: [35, 33, 34], state: "minecraft:stone"},
        {pos: [35, 33, 35], state: "minecraft:cyan_terracotta"},
        {pos: [35, 33, 36], state: "minecraft:cyan_terracotta"},
        {pos: [36, 33, 34], state: "minecraft:cyan_terracotta"},
        {pos: [36, 33, 35], state: "minecraft:stone"},
        {pos: [38, 33, 49], state: "minecraft:cyan_terracotta"},
        {pos: [38, 33, 50], state: "minecraft:stone"},
        {pos: [38, 33, 51], state: "minecraft:stone"},
        {pos: [39, 33, 49], state: "minecraft:cyan_terracotta"},
        {pos: [39, 33, 50], state: "minecraft:cyan_terracotta"},
        {pos: [39, 33, 51], state: "minecraft:stone"},
        {pos: [40, 33, 48], state: "minecraft:stone"},
        {pos: [40, 33, 49], state: "minecraft:cyan_terracotta"},
        {pos: [40, 33, 50], state: "minecraft:cyan_terracotta"},
        {pos: [40, 33, 51], state: "minecraft:stone"},
        {pos: [41, 33, 48], state: "minecraft:stone"},
        {pos: [41, 33, 49], state: "minecraft:cyan_terracotta"},
        {pos: [41, 33, 50], state: "minecraft:cyan_terracotta"},
        {pos: [42, 33, 49], state: "minecraft:cyan_terracotta"},
        {pos: [50, 33, 34], state: "minecraft:cyan_terracotta"},
        {pos: [50, 33, 35], state: "minecraft:cyan_terracotta"},
        {pos: [51, 33, 32], state: "minecraft:stone"},
        {pos: [51, 33, 33], state: "minecraft:cyan_terracotta"},
        {pos: [51, 33, 34], state: "minecraft:cyan_terracotta"},
        {pos: [51, 33, 35], state: "minecraft:cyan_terracotta"},
        {pos: [51, 33, 36], state: "minecraft:stone"},
        {pos: [51, 33, 54], state: "minecraft:cyan_terracotta"},
        {pos: [52, 33, 32], state: "minecraft:cyan_terracotta"},
        {pos: [52, 33, 33], state: "minecraft:stone"},
        {pos: [52, 33, 34], state: "minecraft:cyan_terracotta"},
        {pos: [52, 33, 35], state: "minecraft:stone"},
        {pos: [52, 33, 36], state: "minecraft:cyan_terracotta"},
        {pos: [52, 33, 53], state: "minecraft:cyan_terracotta"},
        {pos: [52, 33, 54], state: "minecraft:cyan_terracotta"},
        {pos: [53, 33, 32], state: "minecraft:cyan_terracotta"},
        {pos: [53, 33, 33], state: "minecraft:cyan_terracotta"},
        {pos: [53, 33, 34], state: "minecraft:stone"},
        {pos: [53, 33, 35], state: "minecraft:cyan_terracotta"},
        {pos: [53, 33, 53], state: "minecraft:cyan_terracotta"},
        {pos: [55, 33, 26], state: "minecraft:water{level:8}"},
        {pos: [56, 33, 27], state: "minecraft:water{level:8}"},
        {pos: [57, 33, 27], state: "minecraft:water{level:8}"},
        {pos: [58, 33, 28], state: "minecraft:water{level:8}"},
        {pos: [61, 33, 52], state: "minecraft:stone"},
        {pos: [61, 33, 53], state: "minecraft:stone"},
        {pos: [62, 33, 51], state: "minecraft:stone"},
        {pos: [62, 33, 52], state: "minecraft:cyan_terracotta"},
        {pos: [62, 33, 53], state: "minecraft:cyan_terracotta"},
        {pos: [62, 33, 54], state: "minecraft:stone"},
        {pos: [63, 33, 50], state: "minecraft:cyan_terracotta"},
        {pos: [63, 33, 51], state: "minecraft:cyan_terracotta"},
        {pos: [63, 33, 52], state: "minecraft:cyan_terracotta"},
        {pos: [63, 33, 53], state: "minecraft:stone"},
        {pos: [63, 33, 54], state: "minecraft:cyan_terracotta"},
        {pos: [64, 33, 50], state: "minecraft:cyan_terracotta"},
        {pos: [64, 33, 51], state: "minecraft:stone"},
        {pos: [64, 33, 52], state: "minecraft:stone"},
        {pos: [64, 33, 53], state: "minecraft:stone"},
        {pos: [64, 33, 54], state: "minecraft:cyan_terracotta"},
        {pos: [65, 33, 51], state: "minecraft:cyan_terracotta"},
        {pos: [65, 33, 52], state: "minecraft:stone"},
        {pos: [65, 33, 53], state: "minecraft:stone"},
        {pos: [33, 34, 35], state: "minecraft:cyan_terracotta"},
        {pos: [33, 34, 36], state: "minecraft:stone"},
        {pos: [33, 34, 37], state: "minecraft:stone"},
        {pos: [34, 34, 34], state: "minecraft:cyan_terracotta"},
        {pos: [34, 34, 35], state: "minecraft:cyan_terracotta"},
        {pos: [34, 34, 36], state: "minecraft:stone"},
        {pos: [34, 34, 37], state: "minecraft:stone"},
        {pos: [35, 34, 33], state: "minecraft:stone"},
        {pos: [35, 34, 34], state: "minecraft:cyan_terracotta"},
        {pos: [35, 34, 35], state: "minecraft:cyan_terracotta"},
        {pos: [35, 34, 36], state: "minecraft:stone"},
        {pos: [36, 34, 33], state: "minecraft:cyan_terracotta"},
        {pos: [36, 34, 34], state: "minecraft:cyan_terracotta"},
        {pos: [36, 34, 35], state: "minecraft:cyan_terracotta"},
        {pos: [37, 34, 49], state: "minecraft:stone"},
        {pos: [37, 34, 50], state: "minecraft:cyan_terracotta"},
        {pos: [38, 34, 49], state: "minecraft:stone"},
        {pos: [38, 34, 50], state: "minecraft:cyan_terracotta"},
        {pos: [38, 34, 51], state: "minecraft:stone"},
        {pos: [38, 34, 52], state: "minecraft:stone"},
        {pos: [39, 34, 48], state: "minecraft:stone"},
        {pos: [39, 34, 49], state: "minecraft:stone"},
        {pos: [39, 34, 50], state: "minecraft:cyan_terracotta"},
        {pos: [39, 34, 51], state: "minecraft:stone"},
        {pos: [39, 34, 52], state: "minecraft:cyan_terracotta"},
        {pos: [40, 34, 48], state: "minecraft:stone"},
        {pos: [40, 34, 49], state: "minecraft:cyan_terracotta"},
        {pos: [40, 34, 50], state: "minecraft:cyan_terracotta"},
        {pos: [40, 34, 51], state: "minecraft:cyan_terracotta"},
        {pos: [40, 34, 52], state: "minecraft:cyan_terracotta"},
        {pos: [41, 34, 48], state: "minecraft:cyan_terracotta"},
        {pos: [41, 34, 49], state: "minecraft:cyan_terracotta"},
        {pos: [41, 34, 50], state: "minecraft:cyan_terracotta"},
        {pos: [41, 34, 51], state: "minecraft:stone"},
        {pos: [42, 34, 49], state: "minecraft:cyan_terracotta"},
        {pos: [50, 34, 33], state: "minecraft:stone"},
        {pos: [50, 34, 34], state: "minecraft:stone"},
        {pos: [50, 34, 35], state: "minecraft:stone"},
        {pos: [50, 34, 36], state: "minecraft:cyan_terracotta"},
        {pos: [51, 34, 32], state: "minecraft:cyan_terracotta"},
        {pos: [51, 34, 33], state: "minecraft:stone"},
        {pos: [51, 34, 34], state: "minecraft:cyan_terracotta"},
        {pos: [51, 34, 35], state: "minecraft:stone"},
        {pos: [51, 34, 36], state: "minecraft:cyan_terracotta"},
        {pos: [51, 34, 54], state: "minecraft:stone"},
        {pos: [52, 34, 32], state: "minecraft:stone"},
        {pos: [52, 34, 33], state: "minecraft:stone"},
        {pos: [52, 34, 34], state: "minecraft:cyan_terracotta"},
        {pos: [52, 34, 35], state: "minecraft:stone"},
        {pos: [52, 34, 36], state: "minecraft:stone"},
        {pos: [52, 34, 53], state: "minecraft:stone"},
        {pos: [52, 34, 54], state: "minecraft:cyan_terracotta"},
        {pos: [53, 34, 32], state: "minecraft:stone"},
        {pos: [53, 34, 33], state: "minecraft:stone"},
        {pos: [53, 34, 34], state: "minecraft:cyan_terracotta"},
        {pos: [53, 34, 35], state: "minecraft:cyan_terracotta"},
        {pos: [53, 34, 36], state: "minecraft:cyan_terracotta"},
        {pos: [53, 34, 53], state: "minecraft:cyan_terracotta"},
        {pos: [53, 34, 54], state: "minecraft:cyan_terracotta"},
        {pos: [55, 34, 26], state: "minecraft:water{level:8}"},
        {pos: [56, 34, 27], state: "minecraft:water{level:8}"},
        {pos: [57, 34, 27], state: "minecraft:water{level:8}"},
        {pos: [58, 34, 28], state: "minecraft:water{level:8}"},
        {pos: [61, 34, 51], state: "minecraft:cyan_terracotta"},
        {pos: [61, 34, 52], state: "minecraft:cyan_terracotta"},
        {pos: [61, 34, 53], state: "minecraft:stone"},
        {pos: [62, 34, 50], state: "minecraft:stone"},
        {pos: [62, 34, 51], state: "minecraft:stone"},
        {pos: [62, 34, 52], state: "minecraft:stone"},
        {pos: [62, 34, 53], state: "minecraft:cyan_terracotta"},
        {pos: [62, 34, 54], state: "minecraft:cyan_terracotta"},
        {pos: [63, 34, 50], state: "minecraft:cyan_terracotta"},
        {pos: [63, 34, 51], state: "minecraft:cyan_terracotta"},
        {pos: [63, 34, 52], state: "minecraft:cyan_terracotta"},
        {pos: [63, 34, 53], state: "minecraft:stone"},
        {pos: [63, 34, 54], state: "minecraft:cyan_terracotta"},
        {pos: [64, 34, 50], state: "minecraft:cyan_terracotta"},
        {pos: [64, 34, 51], state: "minecraft:stone"},
        {pos: [64, 34, 52], state: "minecraft:stone"},
        {pos: [64, 34, 53], state: "minecraft:stone"},
        {pos: [64, 34, 54], state: "minecraft:cyan_terracotta"},
        {pos: [65, 34, 51], state: "minecraft:cyan_terracotta"},
        {pos: [65, 34, 52], state: "minecraft:cyan_terracotta"},
        {pos: [65, 34, 53], state: "minecraft:stone"},
        {pos: [33, 35, 35], state: "minecraft:cyan_terracotta"},
        {pos: [33, 35, 36], state: "minecraft:stone"},
        {pos: [33, 35, 37], state: "minecraft:stone"},
        {pos: [34, 35, 33], state: "minecraft:stone"},
        {pos: [34, 35, 34], state: "minecraft:cyan_terracotta"},
        {pos: [34, 35, 35], state: "minecraft:stone"},
        {pos: [34, 35, 36], state: "minecraft:cyan_terracotta"},
        {pos: [34, 35, 37], state: "minecraft:cyan_terracotta"},
        {pos: [34, 35, 38], state: "minecraft:cyan_terracotta"},
        {pos: [35, 35, 33], state: "minecraft:stone"},
        {pos: [35, 35, 34], state: "minecraft:stone"},
        {pos: [35, 35, 35], state: "minecraft:stone"},
        {pos: [35, 35, 36], state: "minecraft:cyan_terracotta"},
        {pos: [35, 35, 37], state: "minecraft:cyan_terracotta"},
        {pos: [36, 35, 33], state: "minecraft:stone"},
        {pos: [36, 35, 34], state: "minecraft:stone"},
        {pos: [36, 35, 35], state: "minecraft:cyan_terracotta"},
        {pos: [37, 35, 49], state: "minecraft:cyan_terracotta"},
        {pos: [37, 35, 50], state: "minecraft:stone"},
        {pos: [37, 35, 51], state: "minecraft:stone"},
        {pos: [38, 35, 48], state: "minecraft:cyan_terracotta"},
        {pos: [38, 35, 49], state: "minecraft:stone"},
        {pos: [38, 35, 50], state: "minecraft:stone"},
        {pos: [38, 35, 51], state: "minecraft:cyan_terracotta"},
        {pos: [38, 35, 52], state: "minecraft:stone"},
        {pos: [39, 35, 48], state: "minecraft:cyan_terracotta"},
        {pos: [39, 35, 49], state: "minecraft:stone"},
        {pos: [39, 35, 50], state: "minecraft:cyan_terracotta"},
        {pos: [39, 35, 51], state: "minecraft:stone"},
        {pos: [39, 35, 52], state: "minecraft:stone"},
        {pos: [40, 35, 48], state: "minecraft:stone"},
        {pos: [40, 35, 49], state: "minecraft:stone"},
        {pos: [40, 35, 50], state: "minecraft:cyan_terracotta"},
        {pos: [40, 35, 51], state: "minecraft:cyan_terracotta"},
        {pos: [40, 35, 52], state: "minecraft:cyan_terracotta"},
        {pos: [41, 35, 48], state: "minecraft:cyan_terracotta"},
        {pos: [41, 35, 49], state: "minecraft:cyan_terracotta"},
        {pos: [41, 35, 50], state: "minecraft:stone"},
        {pos: [41, 35, 51], state: "minecraft:cyan_terracotta"},
        {pos: [42, 35, 49], state: "minecraft:stone"},
        {pos: [42, 35, 50], state: "minecraft:stone"},
        {pos: [50, 35, 33], state: "minecraft:cyan_terracotta"},
        {pos: [50, 35, 34], state: "minecraft:stone"},
        {pos: [50, 35, 35], state: "minecraft:cyan_terracotta"},
        {pos: [50, 35, 36], state: "minecraft:stone"},
        {pos: [51, 35, 32], state: "minecraft:stone"},
        {pos: [51, 35, 33], state: "minecraft:cyan_terracotta"},
        {pos: [51, 35, 34], state: "minecraft:stone"},
        {pos: [51, 35, 35], state: "minecraft:stone"},
        {pos: [51, 35, 36], state: "minecraft:stone"},
        {pos: [51, 35, 37], state: "minecraft:stone"},
        {pos: [51, 35, 53], state: "minecraft:stone"},
        {pos: [51, 35, 54], state: "minecraft:stone"},
        {pos: [51, 35, 55], state: "minecraft:stone"},
        {pos: [52, 35, 32], state: "minecraft:cyan_terracotta"},
        {pos: [52, 35, 33], state: "minecraft:cyan_terracotta"},
        {pos: [52, 35, 34], state: "minecraft:stone"},
        {pos: [52, 35, 35], state: "minecraft:stone"},
        {pos: [52, 35, 36], state: "minecraft:cyan_terracotta"},
        {pos: [52, 35, 53], state: "minecraft:stone"},
        {pos: [52, 35, 54], state: "minecraft:cyan_terracotta"},
        {pos: [52, 35, 55], state: "minecraft:cyan_terracotta"},
        {pos: [53, 35, 32], state: "minecraft:cyan_terracotta"},
        {pos: [53, 35, 33], state: "minecraft:stone"},
        {pos: [53, 35, 34], state: "minecraft:cyan_terracotta"},
        {pos: [53, 35, 35], state: "minecraft:cyan_terracotta"},
        {pos: [53, 35, 36], state: "minecraft:cyan_terracotta"},
        {pos: [53, 35, 52], state: "minecraft:stone"},
        {pos: [53, 35, 53], state: "minecraft:stone"},
        {pos: [53, 35, 54], state: "minecraft:stone"},
        {pos: [54, 35, 33], state: "minecraft:cyan_terracotta"},
        {pos: [54, 35, 34], state: "minecraft:cyan_terracotta"},
        {pos: [55, 35, 26], state: "minecraft:water{level:8}"},
        {pos: [56, 35, 27], state: "minecraft:water{level:8}"},
        {pos: [57, 35, 27], state: "minecraft:water{level:8}"},
        {pos: [58, 35, 28], state: "minecraft:water{level:8}"},
        {pos: [61, 35, 51], state: "minecraft:cyan_terracotta"},
        {pos: [61, 35, 52], state: "minecraft:cyan_terracotta"},
        {pos: [61, 35, 53], state: "minecraft:cyan_terracotta"},
        {pos: [61, 35, 54], state: "minecraft:cyan_terracotta"},
        {pos: [62, 35, 50], state: "minecraft:stone"},
        {pos: [62, 35, 51], state: "minecraft:cyan_terracotta"},
        {pos: [62, 35, 52], state: "minecraft:stone"},
        {pos: [62, 35, 53], state: "minecraft:stone"},
        {pos: [62, 35, 54], state: "minecraft:cyan_terracotta"},
        {pos: [63, 35, 50], state: "minecraft:cyan_terracotta"},
        {pos: [63, 35, 51], state: "minecraft:cyan_terracotta"},
        {pos: [63, 35, 52], state: "minecraft:cyan_terracotta"},
        {pos: [63, 35, 53], state: "minecraft:cyan_terracotta"},
        {pos: [63, 35, 54], state: "minecraft:stone"},
        {pos: [64, 35, 50], state: "minecraft:cyan_terracotta"},
        {pos: [64, 35, 51], state: "minecraft:cyan_terracotta"},
        {pos: [64, 35, 52], state: "minecraft:cyan_terracotta"},
        {pos: [64, 35, 53], state: "minecraft:stone"},
        {pos: [64, 35, 54], state: "minecraft:cyan_terracotta"},
        {pos: [65, 35, 50], state: "minecraft:cyan_terracotta"},
        {pos: [65, 35, 51], state: "minecraft:stone"},
        {pos: [65, 35, 52], state: "minecraft:stone"},
        {pos: [65, 35, 53], state: "minecraft:cyan_terracotta"},
        {pos: [33, 36, 34], state: "minecraft:cyan_terracotta"},
        {pos: [33, 36, 35], state: "minecraft:stone"},
        {pos: [33, 36, 36], state: "minecraft:stone"},
        {pos: [33, 36, 37], state: "minecraft:stone"},
        {pos: [33, 36, 38], state: "minecraft:stone"},
        {pos: [34, 36, 33], state: "minecraft:stone"},
        {pos: [34, 36, 34], state: "minecraft:cyan_terracotta"},
        {pos: [34, 36, 35], state: "minecraft:stone"},
        {pos: [34, 36, 36], state: "minecraft:cyan_terracotta"},
        {pos: [34, 36, 37], state: "minecraft:cyan_terracotta"},
        {pos: [34, 36, 38], state: "minecraft:stone"},
        {pos: [35, 36, 33], state: "minecraft:cyan_terracotta"},
        {pos: [35, 36, 34], state: "minecraft:stone"},
        {pos: [35, 36, 35], state: "minecraft:cyan_terracotta"},
        {pos: [35, 36, 36], state: "minecraft:cyan_terracotta"},
        {pos: [35, 36, 37], state: "minecraft:stone"},
        {pos: [36, 36, 33], state: "minecraft:stone"},
        {pos: [36, 36, 34], state: "minecraft:cyan_terracotta"},
        {pos: [36, 36, 35], state: "minecraft:cyan_terracotta"},
        {pos: [36, 36, 36], state: "minecraft:cyan_terracotta"},
        {pos: [37, 36, 33], state: "minecraft:stone"},
        {pos: [37, 36, 34], state: "minecraft:stone"},
        {pos: [37, 36, 49], state: "minecraft:cyan_terracotta"},
        {pos: [37, 36, 50], state: "minecraft:cyan_terracotta"},
        {pos: [37, 36, 51], state: "minecraft:cyan_terracotta"},
        {pos: [38, 36, 48], state: "minecraft:cyan_terracotta"},
        {pos: [38, 36, 49], state: "minecraft:stone"},
        {pos: [38, 36, 50], state: "minecraft:stone"},
        {pos: [38, 36, 51], state: "minecraft:stone"},
        {pos: [38, 36, 52], state: "minecraft:cyan_terracotta"},
        {pos: [39, 36, 48], state: "minecraft:stone"},
        {pos: [39, 36, 49], state: "minecraft:stone"},
        {pos: [39, 36, 50], state: "minecraft:cyan_terracotta"},
        {pos: [39, 36, 51], state: "minecraft:stone"},
        {pos: [39, 36, 52], state: "minecraft:cyan_terracotta"},
        {pos: [40, 36, 48], state: "minecraft:cyan_terracotta"},
        {pos: [40, 36, 49], state: "minecraft:cyan_terracotta"},
        {pos: [40, 36, 50], state: "minecraft:cyan_terracotta"},
        {pos: [40, 36, 51], state: "minecraft:cyan_terracotta"},
        {pos: [40, 36, 52], state: "minecraft:stone"},
        {pos: [41, 36, 48], state: "minecraft:stone"},
        {pos: [41, 36, 49], state: "minecraft:cyan_terracotta"},
        {pos: [41, 36, 50], state: "minecraft:stone"},
        {pos: [41, 36, 51], state: "minecraft:cyan_terracotta"},
        {pos: [42, 36, 48], state: "minecraft:stone"},
        {pos: [42, 36, 49], state: "minecraft:stone"},
        {pos: [42, 36, 50], state: "minecraft:cyan_terracotta"},
        {pos: [49, 36, 35], state: "minecraft:cyan_terracotta"},
        {pos: [50, 36, 33], state: "minecraft:stone"},
        {pos: [50, 36, 34], state: "minecraft:stone"},
        {pos: [50, 36, 35], state: "minecraft:stone"},
        {pos: [50, 36, 36], state: "minecraft:stone"},
        {pos: [51, 36, 32], state: "minecraft:cyan_terracotta"},
        {pos: [51, 36, 33], state: "minecraft:stone"},
        {pos: [51, 36, 34], state: "minecraft:cyan_terracotta"},
        {pos: [51, 36, 35], state: "minecraft:cyan_terracotta"},
        {pos: [51, 36, 36], state: "minecraft:stone"},
        {pos: [51, 36, 37], state: "minecraft:stone"},
        {pos: [51, 36, 53], state: "minecraft:stone"},
        {pos: [51, 36, 54], state: "minecraft:stone"},
        {pos: [51, 36, 55], state: "minecraft:cyan_terracotta"},
        {pos: [52, 36, 32], state: "minecraft:stone"},
        {pos: [52, 36, 33], state: "minecraft:stone"},
        {pos: [52, 36, 34], state: "minecraft:cyan_terracotta"},
        {pos: [52, 36, 35], state: "minecraft:cyan_terracotta"},
        {pos: [52, 36, 36], state: "minecraft:stone"},
        {pos: [52, 36, 37], state: "minecraft:cyan_terracotta"},
        {pos: [52, 36, 52], state: "minecraft:stone"},
        {pos: [52, 36, 53], state: "minecraft:stone"},
        {pos: [52, 36, 54], state: "minecraft:cyan_terracotta"},
        {pos: [52, 36, 55], state: "minecraft:stone"},
        {pos: [53, 36, 32], state: "minecraft:cyan_terracotta"},
        {pos: [53, 36, 33], state: "minecraft:stone"},
        {pos: [53, 36, 34], state: "minecraft:stone"},
        {pos: [53, 36, 35], state: "minecraft:cyan_terracotta"},
        {pos: [53, 36, 36], state: "minecraft:cyan_terracotta"},
        {pos: [53, 36, 52], state: "minecraft:stone"},
        {pos: [53, 36, 53], state: "minecraft:cyan_terracotta"},
        {pos: [53, 36, 54], state: "minecraft:stone"},
        {pos: [54, 36, 33], state: "minecraft:cyan_terracotta"},
        {pos: [54, 36, 34], state: "minecraft:cyan_terracotta"},
        {pos: [55, 36, 26], state: "minecraft:water{level:8}"},
        {pos: [56, 36, 27], state: "minecraft:water{level:8}"},
        {pos: [57, 36, 27], state: "minecraft:water{level:8}"},
        {pos: [58, 36, 28], state: "minecraft:water{level:8}"},
        {pos: [61, 36, 51], state: "minecraft:stone"},
        {pos: [61, 36, 52], state: "minecraft:stone"},
        {pos: [61, 36, 53], state: "minecraft:cyan_terracotta"},
        {pos: [61, 36, 54], state: "minecraft:stone"},
        {pos: [62, 36, 50], state: "minecraft:cyan_terracotta"},
        {pos: [62, 36, 51], state: "minecraft:stone"},
        {pos: [62, 36, 52], state: "minecraft:stone"},
        {pos: [62, 36, 53], state: "minecraft:stone"},
        {pos: [62, 36, 54], state: "minecraft:stone"},
        {pos: [63, 36, 50], state: "minecraft:cyan_terracotta"},
        {pos: [63, 36, 51], state: "minecraft:stone"},
        {pos: [63, 36, 52], state: "minecraft:cyan_terracotta"},
        {pos: [63, 36, 53], state: "minecraft:cyan_terracotta"},
        {pos: [63, 36, 54], state: "minecraft:cyan_terracotta"},
        {pos: [63, 36, 55], state: "minecraft:stone"},
        {pos: [64, 36, 50], state: "minecraft:cyan_terracotta"},
        {pos: [64, 36, 51], state: "minecraft:cyan_terracotta"},
        {pos: [64, 36, 52], state: "minecraft:stone"},
        {pos: [64, 36, 53], state: "minecraft:stone"},
        {pos: [64, 36, 54], state: "minecraft:stone"},
        {pos: [65, 36, 50], state: "minecraft:stone"},
        {pos: [65, 36, 51], state: "minecraft:stone"},
        {pos: [65, 36, 52], state: "minecraft:stone"},
        {pos: [65, 36, 53], state: "minecraft:cyan_terracotta"},
        {pos: [32, 37, 36], state: "minecraft:cyan_terracotta"},
        {pos: [32, 37, 37], state: "minecraft:cyan_terracotta"},
        {pos: [32, 37, 38], state: "minecraft:stone"},
        {pos: [33, 37, 34], state: "minecraft:cyan_terracotta"},
        {pos: [33, 37, 35], state: "minecraft:cyan_terracotta"},
        {pos: [33, 37, 36], state: "minecraft:cyan_terracotta"},
        {pos: [33, 37, 37], state: "minecraft:stone"},
        {pos: [33, 37, 38], state: "minecraft:cyan_terracotta"},
        {pos: [34, 37, 33], state: "minecraft:cyan_terracotta"},
        {pos: [34, 37, 34], state: "minecraft:cyan_terracotta"},
        {pos: [34, 37, 35], state: "minecraft:cyan_terracotta"},
        {pos: [34, 37, 36], state: "minecraft:stone"},
        {pos: [34, 37, 37], state: "minecraft:stone"},
        {pos: [34, 37, 38], state: "minecraft:stone"},
        {pos: [35, 37, 33], state: "minecraft:stone"},
        {pos: [35, 37, 34], state: "minecraft:stone"},
        {pos: [35, 37, 35], state: "minecraft:stone"},
        {pos: [35, 37, 36], state: "minecraft:cyan_terracotta"},
        {pos: [35, 37, 37], state: "minecraft:cyan_terracotta"},
        {pos: [36, 37, 33], state: "minecraft:cyan_terracotta"},
        {pos: [36, 37, 34], state: "minecraft:cyan_terracotta"},
        {pos: [36, 37, 35], state: "minecraft:stone"},
        {pos: [36, 37, 36], state: "minecraft:cyan_terracotta"},
        {pos: [36, 37, 50], state: "minecraft:stone"},
        {pos: [37, 37, 33], state: "minecraft:stone"},
        {pos: [37, 37, 34], state: "minecraft:cyan_terracotta"},
        {pos: [37, 37, 48], state: "minecraft:cyan_terracotta"},
        {pos: [37, 37, 49], state: "minecraft:stone"},
        {pos: [37, 37, 50], state: "minecraft:stone"},
        {pos: [37, 37, 51], state: "minecraft:cyan_terracotta"},
        {pos: [37, 37, 52], state: "minecraft:cyan_terracotta"},
        {pos: [38, 37, 48], state: "minecraft:stone"},
        {pos: [38, 37, 49], state: "minecraft:stone"},
        {pos: [38, 37, 50], state: "minecraft:cyan_terracotta"},
        {pos: [38, 37, 51], state: "minecraft:stone"},
        {pos: [38, 37, 52], state: "minecraft:stone"},
        {pos: [39, 37, 48], state: "minecraft:stone"},
        {pos: [39, 37, 49], state: "minecraft:cyan_terracotta"},
        {pos: [39, 37, 50], state: "minecraft:cyan_terracotta"},
        {pos: [39, 37, 51], state: "minecraft:stone"},
        {pos: [39, 37, 52], state: "minecraft:stone"},
        {pos: [39, 37, 53], state: "minecraft:cyan_terracotta"},
        {pos: [40, 37, 47], state: "minecraft:cyan_terracotta"},
        {pos: [40, 37, 48], state: "minecraft:stone"},
        {pos: [40, 37, 49], state: "minecraft:cyan_terracotta"},
        {pos: [40, 37, 50], state: "minecraft:stone"},
        {pos: [40, 37, 51], state: "minecraft:stone"},
        {pos: [40, 37, 52], state: "minecraft:cyan_terracotta"},
        {pos: [41, 37, 48], state: "minecraft:stone"},
        {pos: [41, 37, 49], state: "minecraft:cyan_terracotta"},
        {pos: [41, 37, 50], state: "minecraft:cyan_terracotta"},
        {pos: [41, 37, 51], state: "minecraft:stone"},
        {pos: [41, 37, 52], state: "minecraft:cyan_terracotta"},
        {pos: [42, 37, 48], state: "minecraft:stone"},
        {pos: [42, 37, 49], state: "minecraft:cyan_terracotta"},
        {pos: [42, 37, 50], state: "minecraft:cyan_terracotta"},
        {pos: [42, 37, 51], state: "minecraft:stone"},
        {pos: [49, 37, 34], state: "minecraft:cyan_terracotta"},
        {pos: [49, 37, 35], state: "minecraft:cyan_terracotta"},
        {pos: [49, 37, 36], state: "minecraft:stone"},
        {pos: [50, 37, 33], state: "minecraft:cyan_terracotta"},
        {pos: [50, 37, 34], state: "minecraft:cyan_terracotta"},
        {pos: [50, 37, 35], state: "minecraft:cyan_terracotta"},
        {pos: [50, 37, 36], state: "minecraft:cyan_terracotta"},
        {pos: [50, 37, 37], state: "minecraft:stone"},
        {pos: [51, 37, 32], state: "minecraft:stone"},
        {pos: [51, 37, 33], state: "minecraft:cyan_terracotta"},
        {pos: [51, 37, 34], state: "minecraft:cyan_terracotta"},
        {pos: [51, 37, 35], state: "minecraft:stone"},
        {pos: [51, 37, 36], state: "minecraft:stone"},
        {pos: [51, 37, 37], state: "minecraft:stone"},
        {pos: [51, 37, 53], state: "minecraft:stone"},
        {pos: [51, 37, 54], state: "minecraft:cyan_terracotta"},
        {pos: [51, 37, 55], state: "minecraft:stone"},
        {pos: [52, 37, 31], state: "minecraft:stone"},
        {pos: [52, 37, 32], state: "minecraft:stone"},
        {pos: [52, 37, 33], state: "minecraft:stone"},
        {pos: [52, 37, 34], state: "minecraft:stone"},
        {pos: [52, 37, 35], state: "minecraft:stone"},
        {pos: [52, 37, 36], state: "minecraft:stone"},
        {pos: [52, 37, 37], state: "minecraft:cyan_terracotta"},
        {pos: [52, 37, 52], state: "minecraft:cyan_terracotta"},
        {pos: [52, 37, 53], state: "minecraft:cyan_terracotta"},
        {pos: [52, 37, 54], state: "minecraft:stone"},
        {pos: [52, 37, 55], state: "minecraft:cyan_terracotta"},
        {pos: [53, 37, 32], state: "minecraft:cyan_terracotta"},
        {pos: [53, 37, 33], state: "minecraft:stone"},
        {pos: [53, 37, 34], state: "minecraft:cyan_terracotta"},
        {pos: [53, 37, 35], state: "minecraft:cyan_terracotta"},
        {pos: [53, 37, 36], state: "minecraft:stone"},
        {pos: [53, 37, 52], state: "minecraft:stone"},
        {pos: [53, 37, 53], state: "minecraft:cyan_terracotta"},
        {pos: [53, 37, 54], state: "minecraft:stone"},
        {pos: [53, 37, 55], state: "minecraft:cyan_terracotta"},
        {pos: [54, 37, 32], state: "minecraft:stone"},
        {pos: [54, 37, 33], state: "minecraft:cyan_terracotta"},
        {pos: [54, 37, 34], state: "minecraft:stone"},
        {pos: [54, 37, 35], state: "minecraft:cyan_terracotta"},
        {pos: [55, 37, 26], state: "minecraft:water{level:8}"},
        {pos: [56, 37, 27], state: "minecraft:water{level:8}"},
        {pos: [57, 37, 27], state: "minecraft:water{level:8}"},
        {pos: [58, 37, 28], state: "minecraft:water{level:8}"},
        {pos: [61, 37, 51], state: "minecraft:cyan_terracotta"},
        {pos: [61, 37, 52], state: "minecraft:cyan_terracotta"},
        {pos: [61, 37, 53], state: "minecraft:cyan_terracotta"},
        {pos: [61, 37, 54], state: "minecraft:cyan_terracotta"},
        {pos: [62, 37, 50], state: "minecraft:cyan_terracotta"},
        {pos: [62, 37, 51], state: "minecraft:stone"},
        {pos: [62, 37, 52], state: "minecraft:cyan_terracotta"},
        {pos: [62, 37, 53], state: "minecraft:cyan_terracotta"},
        {pos: [62, 37, 54], state: "minecraft:cyan_terracotta"},
        {pos: [62, 37, 55], state: "minecraft:cyan_terracotta"},
        {pos: [63, 37, 50], state: "minecraft:cyan_terracotta"},
        {pos: [63, 37, 51], state: "minecraft:cyan_terracotta"},
        {pos: [63, 37, 52], state: "minecraft:stone"},
        {pos: [63, 37, 53], state: "minecraft:cyan_terracotta"},
        {pos: [63, 37, 54], state: "minecraft:cyan_terracotta"},
        {pos: [63, 37, 55], state: "minecraft:cyan_terracotta"},
        {pos: [64, 37, 50], state: "minecraft:stone"},
        {pos: [64, 37, 51], state: "minecraft:cyan_terracotta"},
        {pos: [64, 37, 52], state: "minecraft:cyan_terracotta"},
        {pos: [64, 37, 53], state: "minecraft:cyan_terracotta"},
        {pos: [64, 37, 54], state: "minecraft:cyan_terracotta"},
        {pos: [65, 37, 50], state: "minecraft:stone"},
        {pos: [65, 37, 51], state: "minecraft:cyan_terracotta"},
        {pos: [65, 37, 52], state: "minecraft:cyan_terracotta"},
        {pos: [65, 37, 53], state: "minecraft:cyan_terracotta"},
        {pos: [32, 38, 35], state: "minecraft:stone"},
        {pos: [32, 38, 36], state: "minecraft:cyan_terracotta"},
        {pos: [32, 38, 37], state: "minecraft:stone"},
        {pos: [32, 38, 38], state: "minecraft:cyan_terracotta"},
        {pos: [33, 38, 34], state: "minecraft:cyan_terracotta"},
        {pos: [33, 38, 35], state: "minecraft:stone"},
        {pos: [33, 38, 36], state: "minecraft:cyan_terracotta"},
        {pos: [33, 38, 37], state: "minecraft:cyan_terracotta"},
        {pos: [33, 38, 38], state: "minecraft:stone"},
        {pos: [34, 38, 33], state: "minecraft:stone"},
        {pos: [34, 38, 34], state: "minecraft:stone"},
        {pos: [34, 38, 35], state: "minecraft:stone"},
        {pos: [34, 38, 36], state: "minecraft:cyan_terracotta"},
        {pos: [34, 38, 37], state: "minecraft:stone"},
        {pos: [34, 38, 38], state: "minecraft:cyan_terracotta"},
        {pos: [34, 38, 39], state: "minecraft:cyan_terracotta"},
        {pos: [35, 38, 32], state: "minecraft:cyan_terracotta"},
        {pos: [35, 38, 33], state: "minecraft:stone"},
        {pos: [35, 38, 34], state: "minecraft:stone"},
        {pos: [35, 38, 35], state: "minecraft:stone"},
        {pos: [35, 38, 36], state: "minecraft:cyan_terracotta"},
        {pos: [35, 38, 37], state: "minecraft:stone"},
        {pos: [36, 38, 32], state: "minecraft:stone"},
        {pos: [36, 38, 33], state: "minecraft:stone"},
        {pos: [36, 38, 34], state: "minecraft:stone"},
        {pos: [36, 38, 35], state: "minecraft:stone"},
        {pos: [36, 38, 36], state: "minecraft:cyan_terracotta"},
        {pos: [36, 38, 49], state: "minecraft:cyan_terracotta"},
        {pos: [36, 38, 50], state: "minecraft:cyan_terracotta"},
        {pos: [36, 38, 51], state: "minecraft:cyan_terracotta"},
        {pos: [37, 38, 33], state: "minecraft:cyan_terracotta"},
        {pos: [37, 38, 34], state: "minecraft:cyan_terracotta"},
        {pos: [37, 38, 35], state: "minecraft:stone"},
        {pos: [37, 38, 48], state: "minecraft:cyan_terracotta"},
        {pos: [37, 38, 49], state: "minecraft:cyan_terracotta"},
        {pos: [37, 38, 50], state: "minecraft:stone"},
        {pos: [37, 38, 51], state: "minecraft:stone"},
        {pos: [37, 38, 52], state: "minecraft:cyan_terracotta"},
        {pos: [37, 38, 53], state: "minecraft:stone"},
        {pos: [38, 38, 48], state: "minecraft:stone"},
        {pos: [38, 38, 49], state: "minecraft:stone"},
        {pos: [38, 38, 50], state: "minecraft:stone"},
        {pos: [38, 38, 51], state: "minecraft:cyan_terracotta"},
        {pos: [38, 38, 52], state: "minecraft:cyan_terracotta"},
        {pos: [38, 38, 53], state: "minecraft:cyan_terracotta"},
        {pos: [39, 38, 47], state: "minecraft:cyan_terracotta"},
        {pos: [39, 38, 48], state: "minecraft:cyan_terracotta"},
        {pos: [39, 38, 49], state: "minecraft:cyan_terracotta"},
        {pos: [39, 38, 50], state: "minecraft:stone"},
        {pos: [39, 38, 51], state: "minecraft:stone"},
        {pos: [39, 38, 52], state: "minecraft:cyan_terracotta"},
        {pos: [39, 38, 53], state: "minecraft:cyan_terracotta"},
        {pos: [40, 38, 47], state: "minecraft:stone"},
        {pos: [40, 38, 48], state: "minecraft:cyan_terracotta"},
        {pos: [40, 38, 49], state: "minecraft:stone"},
        {pos: [40, 38, 50], state: "minecraft:cyan_terracotta"},
        {pos: [40, 38, 51], state: "minecraft:cyan_terracotta"},
        {pos: [40, 38, 52], state: "minecraft:stone"},
        {pos: [40, 38, 53], state: "minecraft:stone"},
        {pos: [41, 38, 47], state: "minecraft:stone"},
        {pos: [41, 38, 48], state: "minecraft:stone"},
        {pos: [41, 38, 49], state: "minecraft:cyan_terracotta"},
        {pos: [41, 38, 50], state: "minecraft:stone"},
        {pos: [41, 38, 51], state: "minecraft:cyan_terracotta"},
        {pos: [41, 38, 52], state: "minecraft:cyan_terracotta"},
        {pos: [42, 38, 47], state: "minecraft:cyan_terracotta"},
        {pos: [42, 38, 48], state: "minecraft:stone"},
        {pos: [42, 38, 49], state: "minecraft:stone"},
        {pos: [42, 38, 50], state: "minecraft:stone"},
        {pos: [42, 38, 51], state: "minecraft:stone"},
        {pos: [43, 38, 48], state: "minecraft:stone"},
        {pos: [43, 38, 49], state: "minecraft:stone"},
        {pos: [49, 38, 33], state: "minecraft:cyan_terracotta"},
        {pos: [49, 38, 34], state: "minecraft:stone"},
        {pos: [49, 38, 35], state: "minecraft:cyan_terracotta"},
        {pos: [49, 38, 36], state: "minecraft:cyan_terracotta"},
        {pos: [50, 38, 33], state: "minecraft:cyan_terracotta"},
        {pos: [50, 38, 34], state: "minecraft:cyan_terracotta"},
        {pos: [50, 38, 35], state: "minecraft:cyan_terracotta"},
        {pos: [50, 38, 36], state: "minecraft:cyan_terracotta"},
        {pos: [50, 38, 37], state: "minecraft:cyan_terracotta"},
        {pos: [50, 38, 54], state: "minecraft:stone"},
        {pos: [51, 38, 32], state: "minecraft:cyan_terracotta"},
        {pos: [51, 38, 33], state: "minecraft:stone"},
        {pos: [51, 38, 34], state: "minecraft:cyan_terracotta"},
        {pos: [51, 38, 35], state: "minecraft:cyan_terracotta"},
        {pos: [51, 38, 36], state: "minecraft:stone"},
        {pos: [51, 38, 37], state: "minecraft:cyan_terracotta"},
        {pos: [51, 38, 52], state: "minecraft:stone"},
        {pos: [51, 38, 53], state: "minecraft:stone"},
        {pos: [51, 38, 54], state: "minecraft:stone"},
        {pos: [51, 38, 55], state: "minecraft:stone"},
        {pos: [52, 38, 31], state: "minecraft:stone"},
        {pos: [52, 38, 32], state: "minecraft:stone"},
        {pos: [52, 38, 33], state: "minecraft:stone"},
        {pos: [52, 38, 34], state: "minecraft:cyan_terracotta"},
        {pos: [52, 38, 35], state: "minecraft:cyan_terracotta"},
        {pos: [52, 38, 36], state: "minecraft:cyan_terracotta"},
        {pos: [52, 38, 37], state: "minecraft:cyan_terracotta"},
        {pos: [52, 38, 52], state: "minecraft:cyan_terracotta"},
        {pos: [52, 38, 53], state: "minecraft:stone"},
        {pos: [52, 38, 54], state: "minecraft:stone"},
        {pos: [52, 38, 55], state: "minecraft:cyan_terracotta"},
        {pos: [53, 38, 32], state: "minecraft:stone"},
        {pos: [53, 38, 33], state: "minecraft:stone"},
        {pos: [53, 38, 34], state: "minecraft:stone"},
        {pos: [53, 38, 35], state: "minecraft:cyan_terracotta"},
        {pos: [53, 38, 36], state: "minecraft:cyan_terracotta"},
        {pos: [53, 38, 52], state: "minecraft:cyan_terracotta"},
        {pos: [53, 38, 53], state: "minecraft:stone"},
        {pos: [53, 38, 54], state: "minecraft:cyan_terracotta"},
        {pos: [53, 38, 55], state: "minecraft:stone"},
        {pos: [54, 38, 32], state: "minecraft:stone"},
        {pos: [54, 38, 33], state: "minecraft:stone"},
        {pos: [54, 38, 34], state: "minecraft:stone"},
        {pos: [54, 38, 35], state: "minecraft:cyan_terracotta"},
        {pos: [54, 38, 53], state: "minecraft:stone"},
        {pos: [54, 38, 54], state: "minecraft:cyan_terracotta"},
        {pos: [55, 38, 26], state: "minecraft:water{level:8}"},
        {pos: [56, 38, 27], state: "minecraft:water{level:8}"},
        {pos: [57, 38, 27], state: "minecraft:water{level:8}"},
        {pos: [58, 38, 28], state: "minecraft:water{level:8}"},
        {pos: [60, 38, 52], state: "minecraft:stone"},
        {pos: [61, 38, 51], state: "minecraft:stone"},
        {pos: [61, 38, 52], state: "minecraft:stone"},
        {pos: [61, 38, 53], state: "minecraft:stone"},
        {pos: [61, 38, 54], state: "minecraft:stone"},
        {pos: [62, 38, 50], state: "minecraft:cyan_terracotta"},
        {pos: [62, 38, 51], state: "minecraft:cyan_terracotta"},
        {pos: [62, 38, 52], state: "minecraft:stone"},
        {pos: [62, 38, 53], state: "minecraft:cyan_terracotta"},
        {pos: [62, 38, 54], state: "minecraft:cyan_terracotta"},
        {pos: [62, 38, 55], state: "minecraft:stone"},
        {pos: [63, 38, 49], state: "minecraft:cyan_terracotta"},
        {pos: [63, 38, 50], state: "minecraft:stone"},
        {pos: [63, 38, 51], state: "minecraft:stone"},
        {pos: [63, 38, 52], state: "minecraft:cyan_terracotta"},
        {pos: [63, 38, 53], state: "minecraft:cyan_terracotta"},
        {pos: [63, 38, 54], state: "minecraft:stone"},
        {pos: [63, 38, 55], state: "minecraft:cyan_terracotta"},
        {pos: [64, 38, 49], state: "minecraft:stone"},
        {pos: [64, 38, 50], state: "minecraft:cyan_terracotta"},
        {pos: [64, 38, 51], state: "minecraft:stone"},
        {pos: [64, 38, 52], state: "minecraft:cyan_terracotta"},
        {pos: [64, 38, 53], state: "minecraft:cyan_terracotta"},
        {pos: [64, 38, 54], state: "minecraft:cyan_terracotta"},
        {pos: [64, 38, 55], state: "minecraft:stone"},
        {pos: [65, 38, 50], state: "minecraft:stone"},
        {pos: [65, 38, 51], state: "minecraft:stone"},
        {pos: [65, 38, 52], state: "minecraft:stone"},
        {pos: [65, 38, 53], state: "minecraft:stone"},
        {pos: [65, 38, 54], state: "minecraft:cyan_terracotta"},
        {pos: [32, 39, 35], state: "minecraft:stone"},
        {pos: [32, 39, 36], state: "minecraft:stone"},
        {pos: [32, 39, 37], state: "minecraft:cyan_terracotta"},
        {pos: [32, 39, 38], state: "minecraft:stone"},
        {pos: [33, 39, 34], state: "minecraft:cyan_terracotta"},
        {pos: [33, 39, 35], state: "minecraft:stone"},
        {pos: [33, 39, 36], state: "minecraft:cyan_terracotta"},
        {pos: [33, 39, 37], state: "minecraft:stone"},
        {pos: [33, 39, 38], state: "minecraft:stone"},
        {pos: [33, 39, 39], state: "minecraft:cyan_terracotta"},
        {pos: [34, 39, 32], state: "minecraft:stone"},
        {pos: [34, 39, 33], state: "minecraft:cyan_terracotta"},
        {pos: [34, 39, 34], state: "minecraft:cyan_terracotta"},
        {pos: [34, 39, 35], state: "minecraft:cyan_terracotta"},
        {pos: [34, 39, 36], state: "minecraft:cyan_terracotta"},
        {pos: [34, 39, 37], state: "minecraft:stone"},
        {pos: [34, 39, 38], state: "minecraft:stone"},
        {pos: [34, 39, 39], state: "minecraft:stone"},
        {pos: [35, 39, 32], state: "minecraft:stone"},
        {pos: [35, 39, 33], state: "minecraft:cyan_terracotta"},
        {pos: [35, 39, 34], state: "minecraft:stone"},
        {pos: [35, 39, 35], state: "minecraft:stone"},
        {pos: [35, 39, 36], state: "minecraft:cyan_terracotta"},
        {pos: [35, 39, 37], state: "minecraft:cyan_terracotta"},
        {pos: [35, 39, 38], state: "minecraft:cyan_terracotta"},
        {pos: [36, 39, 32], state: "minecraft:cyan_terracotta"},
        {pos: [36, 39, 33], state: "minecraft:stone"},
        {pos: [36, 39, 34], state: "minecraft:cyan_terracotta"},
        {pos: [36, 39, 35], state: "minecraft:stone"},
        {pos: [36, 39, 36], state: "minecraft:cyan_terracotta"},
        {pos: [36, 39, 37], state: "minecraft:cyan_terracotta"},
        {pos: [36, 39, 49], state: "minecraft:cyan_terracotta"},
        {pos: [36, 39, 50], state: "minecraft:stone"},
        {pos: [36, 39, 51], state: "minecraft:cyan_terracotta"},
        {pos: [37, 39, 33], state: "minecraft:stone"},
        {pos: [37, 39, 34], state: "minecraft:stone"},
        {pos: [37, 39, 35], state: "minecraft:stone"},
        {pos: [37, 39, 48], state: "minecraft:cyan_terracotta"},
        {pos: [37, 39, 49], state: "minecraft:stone"},
        {pos: [37, 39, 50], state: "minecraft:stone"},
        {pos: [37, 39, 51], state: "minecraft:cyan_terracotta"},
        {pos: [37, 39, 52], state: "minecraft:cyan_terracotta"},
        {pos: [37, 39, 53], state: "minecraft:stone"},
        {pos: [38, 39, 48], state: "minecraft:cyan_terracotta"},
        {pos: [38, 39, 49], state: "minecraft:cyan_terracotta"},
        {pos: [38, 39, 50], state: "minecraft:stone"},
        {pos: [38, 39, 51], state: "minecraft:cyan_terracotta"},
        {pos: [38, 39, 52], state: "minecraft:stone"},
        {pos: [38, 39, 53], state: "minecraft:stone"},
        {pos: [39, 39, 47], state: "minecraft:cyan_terracotta"},
        {pos: [39, 39, 48], state: "minecraft:stone"},
        {pos: [39, 39, 49], state: "minecraft:stone"},
        {pos: [39, 39, 50], state: "minecraft:cyan_terracotta"},
        {pos: [39, 39, 51], state: "minecraft:stone"},
        {pos: [39, 39, 52], state: "minecraft:cyan_terracotta"},
        {pos: [39, 39, 53], state: "minecraft:cyan_terracotta"},
        {pos: [40, 39, 47], state: "minecraft:cyan_terracotta"},
        {pos: [40, 39, 48], state: "minecraft:cyan_terracotta"},
        {pos: [40, 39, 49], state: "minecraft:stone"},
        {pos: [40, 39, 50], state: "minecraft:stone"},
        {pos: [40, 39, 51], state: "minecraft:stone"},
        {pos: [40, 39, 52], state: "minecraft:cyan_terracotta"},
        {pos: [40, 39, 53], state: "minecraft:stone"},
        {pos: [41, 39, 47], state: "minecraft:cyan_terracotta"},
        {pos: [41, 39, 48], state: "minecraft:cyan_terracotta"},
        {pos: [41, 39, 49], state: "minecraft:stone"},
        {pos: [41, 39, 50], state: "minecraft:cyan_terracotta"},
        {pos: [41, 39, 51], state: "minecraft:stone"},
        {pos: [41, 39, 52], state: "minecraft:cyan_terracotta"},
        {pos: [42, 39, 47], state: "minecraft:cyan_terracotta"},
        {pos: [42, 39, 48], state: "minecraft:cyan_terracotta"},
        {pos: [42, 39, 49], state: "minecraft:stone"},
        {pos: [42, 39, 50], state: "minecraft:stone"},
        {pos: [42, 39, 51], state: "minecraft:cyan_terracotta"},
        {pos: [43, 39, 48], state: "minecraft:cyan_terracotta"},
        {pos: [43, 39, 49], state: "minecraft:cyan_terracotta"},
        {pos: [49, 39, 33], state: "minecraft:cyan_terracotta"},
        {pos: [49, 39, 34], state: "minecraft:stone"},
        {pos: [49, 39, 35], state: "minecraft:stone"},
        {pos: [49, 39, 36], state: "minecraft:stone"},
        {pos: [50, 39, 32], state: "minecraft:stone"},
        {pos: [50, 39, 33], state: "minecraft:cyan_terracotta"},
        {pos: [50, 39, 34], state: "minecraft:cyan_terracotta"},
        {pos: [50, 39, 35], state: "minecraft:cyan_terracotta"},
        {pos: [50, 39, 36], state: "minecraft:stone"},
        {pos: [50, 39, 37], state: "minecraft:cyan_terracotta"},
        {pos: [50, 39, 53], state: "minecraft:cyan_terracotta"},
        {pos: [50, 39, 54], state: "minecraft:stone"},
        {pos: [50, 39, 55], state: "minecraft:cyan_terracotta"},
        {pos: [51, 39, 32], state: "minecraft:stone"},
        {pos: [51, 39, 33], state: "minecraft:cyan_terracotta"},
        {pos: [51, 39, 34], state: "minecraft:stone"},
        {pos: [51, 39, 35], state: "minecraft:cyan_terracotta"},
        {pos: [51, 39, 36], state: "minecraft:stone"},
        {pos: [51, 39, 37], state: "minecraft:stone"},
        {pos: [51, 39, 38], state: "minecraft:stone"},
        {pos: [51, 39, 52], state: "minecraft:stone"},
        {pos: [51, 39, 53], state: "minecraft:stone"},
        {pos: [51, 39, 54], state: "minecraft:stone"},
        {pos: [51, 39, 55], state: "minecraft:stone"},
        {pos: [52, 39, 31], state: "minecraft:stone"},
        {pos: [52, 39, 32], state: "minecraft:cyan_terracotta"},
        {pos: [52, 39, 33], state: "minecraft:stone"},
        {pos: [52, 39, 34], state: "minecraft:stone"},
        {pos: [52, 39, 35], state: "minecraft:cyan_terracotta"},
        {pos: [52, 39, 36], state: "minecraft:cyan_terracotta"},
        {pos: [52, 39, 37], state: "minecraft:cyan_terracotta"},
        {pos: [52, 39, 52], state: "minecraft:cyan_terracotta"},
        {pos: [52, 39, 53], state: "minecraft:stone"},
        {pos: [52, 39, 54], state: "minecraft:cyan_terracotta"},
        {pos: [52, 39, 55], state: "minecraft:stone"},
        {pos: [53, 39, 31], state: "minecraft:stone"},
        {pos: [53, 39, 32], state: "minecraft:stone"},
        {pos: [53, 39, 33], state: "minecraft:cyan_terracotta"},
        {pos: [53, 39, 34], state: "minecraft:cyan_terracotta"},
        {pos: [53, 39, 35], state: "minecraft:stone"},
        {pos: [53, 39, 36], state: "minecraft:stone"},
        {pos: [53, 39, 37], state: "minecraft:cyan_terracotta"},
        {pos: [53, 39, 52], state: "minecraft:cyan_terracotta"},
        {pos: [53, 39, 53], state: "minecraft:cyan_terracotta"},
        {pos: [53, 39, 54], state: "minecraft:stone"},
        {pos: [53, 39, 55], state: "minecraft:stone"},
        {pos: [54, 39, 32], state: "minecraft:stone"},
        {pos: [54, 39, 33], state: "minecraft:cyan_terracotta"},
        {pos: [54, 39, 34], state: "minecraft:stone"},
        {pos: [54, 39, 35], state: "minecraft:cyan_terracotta"},
        {pos: [54, 39, 52], state: "minecraft:cyan_terracotta"},
        {pos: [54, 39, 53], state: "minecraft:stone"},
        {pos: [54, 39, 54], state: "minecraft:stone"},
        {pos: [55, 39, 26], state: "minecraft:water{level:8}"},
        {pos: [56, 39, 27], state: "minecraft:water{level:8}"},
        {pos: [57, 39, 27], state: "minecraft:water{level:8}"},
        {pos: [58, 39, 28], state: "minecraft:water{level:8}"},
        {pos: [60, 39, 52], state: "minecraft:stone"},
        {pos: [61, 39, 50], state: "minecraft:cyan_terracotta"},
        {pos: [61, 39, 51], state: "minecraft:stone"},
        {pos: [61, 39, 52], state: "minecraft:cyan_terracotta"},
        {pos: [61, 39, 53], state: "minecraft:stone"},
        {pos: [61, 39, 54], state: "minecraft:cyan_terracotta"},
        {pos: [62, 39, 50], state: "minecraft:stone"},
        {pos: [62, 39, 51], state: "minecraft:stone"},
        {pos: [62, 39, 52], state: "minecraft:cyan_terracotta"},
        {pos: [62, 39, 53], state: "minecraft:cyan_terracotta"},
        {pos: [62, 39, 54], state: "minecraft:stone"},
        {pos: [62, 39, 55], state: "minecraft:cyan_terracotta"},
        {pos: [63, 39, 49], state: "minecraft:cyan_terracotta"},
        {pos: [63, 39, 50], state: "minecraft:stone"},
        {pos: [63, 39, 51], state: "minecraft:stone"},
        {pos: [63, 39, 52], state: "minecraft:stone"},
        {pos: [63, 39, 53], state: "minecraft:cyan_terracotta"},
        {pos: [63, 39, 54], state: "minecraft:stone"},
        {pos: [63, 39, 55], state: "minecraft:cyan_terracotta"},
        {pos: [64, 39, 49], state: "minecraft:stone"},
        {pos: [64, 39, 50], state: "minecraft:cyan_terracotta"},
        {pos: [64, 39, 51], state: "minecraft:cyan_terracotta"},
        {pos: [64, 39, 52], state: "minecraft:stone"},
        {pos: [64, 39, 53], state: "minecraft:stone"},
        {pos: [64, 39, 54], state: "minecraft:cyan_terracotta"},
        {pos: [64, 39, 55], state: "minecraft:stone"},
        {pos: [65, 39, 50], state: "minecraft:stone"},
        {pos: [65, 39, 51], state: "minecraft:stone"},
        {pos: [65, 39, 52], state: "minecraft:stone"},
        {pos: [65, 39, 53], state: "minecraft:cyan_terracotta"},
        {pos: [65, 39, 54], state: "minecraft:cyan_terracotta"},
        {pos: [31, 40, 37], state: "minecraft:stone"},
        {pos: [32, 40, 34], state: "minecraft:stone"},
        {pos: [32, 40, 35], state: "minecraft:stone"},
        {pos: [32, 40, 36], state: "minecraft:stone"},
        {pos: [32, 40, 37], state: "minecraft:cyan_terracotta"},
        {pos: [32, 40, 38], state: "minecraft:cyan_terracotta"},
        {pos: [33, 40, 33], state: "minecraft:cyan_terracotta"},
        {pos: [33, 40, 34], state: "minecraft:cyan_terracotta"},
        {pos: [33, 40, 35], state: "minecraft:cyan_terracotta"},
        {pos: [33, 40, 36], state: "minecraft:stone"},
        {pos: [33, 40, 37], state: "minecraft:stone"},
        {pos: [33, 40, 38], state: "minecraft:stone"},
        {pos: [33, 40, 39], state: "minecraft:stone"},
        {pos: [34, 40, 32], state: "minecraft:cyan_terracotta"},
        {pos: [34, 40, 33], state: "minecraft:stone"},
        {pos: [34, 40, 34], state: "minecraft:stone"},
        {pos: [34, 40, 35], state: "minecraft:stone"},
        {pos: [34, 40, 36], state: "minecraft:stone"},
        {pos: [34, 40, 37], state: "minecraft:stone"},
        {pos: [34, 40, 38], state: "minecraft:stone"},
        {pos: [34, 40, 39], state: "minecraft:stone"},
        {pos: [35, 40, 32], state: "minecraft:cyan_terracotta"},
        {pos: [35, 40, 33], state: "minecraft:cyan_terracotta"},
        {pos: [35, 40, 34], state: "minecraft:stone"},
        {pos: [35, 40, 35], state: "minecraft:stone"},
        {pos: [35, 40, 36], state: "minecraft:cyan_terracotta"},
        {pos: [35, 40, 37], state: "minecraft:stone"},
        {pos: [35, 40, 38], state: "minecraft:cyan_terracotta"},
        {pos: [35, 40, 39], state: "minecraft:cyan_terracotta"},
        {pos: [35, 40, 50], state: "minecraft:stone"},
        {pos: [36, 40, 32], state: "minecraft:stone"},
        {pos: [36, 40, 33], state: "minecraft:cyan_terracotta"},
        {pos: [36, 40, 34], state: "minecraft:cyan_terracotta"},
        {pos: [36, 40, 35], state: "minecraft:cyan_terracotta"},
        {pos: [36, 40, 36], state: "minecraft:cyan_terracotta"},
        {pos: [36, 40, 37], state: "minecraft:stone"},
        {pos: [36, 40, 49], state: "minecraft:cyan_terracotta"},
        {pos: [36, 40, 50], state: "minecraft:stone"},
        {pos: [36, 40, 51], state: "minecraft:stone"},
        {pos: [36, 40, 52], state: "minecraft:cyan_terracotta"},
        {pos: [37, 40, 32], state: "minecraft:cyan_terracotta"},
        {pos: [37, 40, 33], state: "minecraft:stone"},
        {pos: [37, 40, 34], state: "minecraft:cyan_terracotta"},
        {pos: [37, 40, 35], state: "minecraft:cyan_terracotta"},
        {pos: [37, 40, 36], state: "minecraft:stone"},
        {pos: [37, 40, 48], state: "minecraft:cyan_terracotta"},
        {pos: [37, 40, 49], state: "minecraft:stone"},
        {pos: [37, 40, 50], state: "minecraft:stone"},
        {pos: [37, 40, 51], state: "minecraft:cyan_terracotta"},
        {pos: [37, 40, 52], state: "minecraft:stone"},
        {pos: [37, 40, 53], state: "minecraft:cyan_terracotta"},
        {pos: [38, 40, 34], state: "minecraft:cyan_terracotta"},
        {pos: [38, 40, 48], state: "minecraft:stone"},
        {pos: [38, 40, 49], state: "minecraft:stone"},
        {pos: [38, 40, 50], state: "minecraft:cyan_terracotta"},
        {pos: [38, 40, 51], state: "minecraft:stone"},
        {pos: [38, 40, 52], state: "minecraft:stone"},
        {pos: [38, 40, 53], state: "minecraft:stone"},
        {pos: [39, 40, 47], state: "minecraft:stone"},
        {pos: [39, 40, 48], state: "minecraft:cyan_terracotta"},
        {pos: [39, 40, 49], state: "minecraft:cyan_terracotta"},
        {pos: [39, 40, 50], state: "minecraft:stone"},
        {pos: [39, 40, 51], state: "minecraft:stone"},
        {pos: [39, 40, 52], state: "minecraft:stone"},
        {pos: [39, 40, 53], state: "minecraft:cyan_terracotta"},
        {pos: [40, 40, 47], state: "minecraft:stone"},
        {pos: [40, 40, 48], state: "minecraft:cyan_terracotta"},
        {pos: [40, 40, 49], state: "minecraft:cyan_terracotta"},
        {pos: [40, 40, 50], state: "minecraft:stone"},
        {pos: [40, 40, 51], state: "minecraft:stone"},
        {pos: [40, 40, 52], state: "minecraft:stone"},
        {pos: [40, 40, 53], state: "minecraft:stone"},
        {pos: [41, 40, 47], state: "minecraft:cyan_terracotta"},
        {pos: [41, 40, 48], state: "minecraft:stone"},
        {pos: [41, 40, 49], state: "minecraft:stone"},
        {pos: [41, 40, 50], state: "minecraft:stone"},
        {pos: [41, 40, 51], state: "minecraft:cyan_terracotta"},
        {pos: [41, 40, 52], state: "minecraft:stone"},
        {pos: [41, 40, 53], state: "minecraft:stone"},
        {pos: [42, 40, 47], state: "minecraft:stone"},
        {pos: [42, 40, 48], state: "minecraft:stone"},
        {pos: [42, 40, 49], state: "minecraft:stone"},
        {pos: [42, 40, 50], state: "minecraft:stone"},
        {pos: [42, 40, 51], state: "minecraft:cyan_terracotta"},
        {pos: [43, 40, 47], state: "minecraft:stone"},
        {pos: [43, 40, 48], state: "minecraft:cyan_terracotta"},
        {pos: [43, 40, 49], state: "minecraft:stone"},
        {pos: [43, 40, 50], state: "minecraft:cyan_terracotta"},
        {pos: [48, 40, 34], state: "minecraft:cyan_terracotta"},
        {pos: [49, 40, 33], state: "minecraft:cyan_terracotta"},
        {pos: [49, 40, 34], state: "minecraft:cyan_terracotta"},
        {pos: [49, 40, 35], state: "minecraft:stone"},
        {pos: [49, 40, 36], state: "minecraft:cyan_terracotta"},
        {pos: [50, 40, 32], state: "minecraft:cyan_terracotta"},
        {pos: [50, 40, 33], state: "minecraft:stone"},
        {pos: [50, 40, 34], state: "minecraft:cyan_terracotta"},
        {pos: [50, 40, 35], state: "minecraft:cyan_terracotta"},
        {pos: [50, 40, 36], state: "minecraft:cyan_terracotta"},
        {pos: [50, 40, 37], state: "minecraft:stone"},
        {pos: [50, 40, 53], state: "minecraft:cyan_terracotta"},
        {pos: [50, 40, 54], state: "minecraft:stone"},
        {pos: [50, 40, 55], state: "minecraft:cyan_terracotta"},
        {pos: [51, 40, 31], state: "minecraft:cyan_terracotta"},
        {pos: [51, 40, 32], state: "minecraft:stone"},
        {pos: [51, 40, 33], state: "minecraft:stone"},
        {pos: [51, 40, 34], state: "minecraft:stone"},
        {pos: [51, 40, 35], state: "minecraft:cyan_terracotta"},
        {pos: [51, 40, 36], state: "minecraft:stone"},
        {pos: [51, 40, 37], state: "minecraft:stone"},
        {pos: [51, 40, 38], state: "minecraft:cyan_terracotta"},
        {pos: [51, 40, 52], state: "minecraft:stone"},
        {pos: [51, 40, 53], state: "minecraft:stone"},
        {pos: [51, 40, 54], state: "minecraft:stone"},
        {pos: [51, 40, 55], state: "minecraft:cyan_terracotta"},
        {pos: [51, 40, 56], state: "minecraft:stone"},
        {pos: [52, 40, 31], state: "minecraft:stone"},
        {pos: [52, 40, 32], state: "minecraft:cyan_terracotta"},
        {pos: [52, 40, 33], state: "minecraft:stone"},
        {pos: [52, 40, 34], state: "minecraft:stone"},
        {pos: [52, 40, 35], state: "minecraft:cyan_terracotta"},
        {pos: [52, 40, 36], state: "minecraft:stone"},
        {pos: [52, 40, 37], state: "minecraft:cyan_terracotta"},
        {pos: [52, 40, 38], state: "minecraft:stone"},
        {pos: [52, 40, 51], state: "minecraft:cyan_terracotta"},
        {pos: [52, 40, 52], state: "minecraft:cyan_terracotta"},
        {pos: [52, 40, 53], state: "minecraft:stone"},
        {pos: [52, 40, 54], state: "minecraft:stone"},
        {pos: [52, 40, 55], state: "minecraft:cyan_terracotta"},
        {pos: [52, 40, 56], state: "minecraft:stone"},
        {pos: [53, 40, 31], state: "minecraft:stone"},
        {pos: [53, 40, 32], state: "minecraft:stone"},
        {pos: [53, 40, 33], state: "minecraft:cyan_terracotta"},
        {pos: [53, 40, 34], state: "minecraft:cyan_terracotta"},
        {pos: [53, 40, 35], state: "minecraft:stone"},
        {pos: [53, 40, 36], state: "minecraft:stone"},
        {pos: [53, 40, 37], state: "minecraft:stone"},
        {pos: [53, 40, 51], state: "minecraft:cyan_terracotta"},
        {pos: [53, 40, 52], state: "minecraft:cyan_terracotta"},
        {pos: [53, 40, 53], state: "minecraft:stone"},
        {pos: [53, 40, 54], state: "minecraft:stone"},
        {pos: [53, 40, 55], state: "minecraft:stone"},
        {pos: [54, 40, 32], state: "minecraft:cyan_terracotta"},
        {pos: [54, 40, 33], state: "minecraft:stone"},
        {pos: [54, 40, 34], state: "minecraft:stone"},
        {pos: [54, 40, 35], state: "minecraft:cyan_terracotta"},
        {pos: [54, 40, 36], state: "minecraft:cyan_terracotta"},
        {pos: [54, 40, 52], state: "minecraft:cyan_terracotta"},
        {pos: [54, 40, 53], state: "minecraft:stone"},
        {pos: [54, 40, 54], state: "minecraft:stone"},
        {pos: [55, 40, 26], state: "minecraft:water{level:8}"},
        {pos: [56, 40, 27], state: "minecraft:water{level:8}"},
        {pos: [57, 40, 27], state: "minecraft:water{level:8}"},
        {pos: [58, 40, 28], state: "minecraft:water{level:8}"},
        {pos: [60, 40, 52], state: "minecraft:cyan_terracotta"},
        {pos: [60, 40, 53], state: "minecraft:cyan_terracotta"},
        {pos: [61, 40, 50], state: "minecraft:stone"},
        {pos: [61, 40, 51], state: "minecraft:stone"},
        {pos: [61, 40, 52], state: "minecraft:stone"},
        {pos: [61, 40, 53], state: "minecraft:cyan_terracotta"},
        {pos: [61, 40, 54], state: "minecraft:cyan_terracotta"},
        {pos: [62, 40, 50], state: "minecraft:stone"},
        {pos: [62, 40, 51], state: "minecraft:cyan_terracotta"},
        {pos: [62, 40, 52], state: "minecraft:cyan_terracotta"},
        {pos: [62, 40, 53], state: "minecraft:stone"},
        {pos: [62, 40, 54], state: "minecraft:cyan_terracotta"},
        {pos: [62, 40, 55], state: "minecraft:cyan_terracotta"},
        {pos: [63, 40, 49], state: "minecraft:stone"},
        {pos: [63, 40, 50], state: "minecraft:cyan_terracotta"},
        {pos: [63, 40, 51], state: "minecraft:stone"},
        {pos: [63, 40, 52], state: "minecraft:cyan_terracotta"},
        {pos: [63, 40, 53], state: "minecraft:cyan_terracotta"},
        {pos: [63, 40, 54], state: "minecraft:cyan_terracotta"},
        {pos: [63, 40, 55], state: "minecraft:stone"},
        {pos: [64, 40, 49], state: "minecraft:cyan_terracotta"},
        {pos: [64, 40, 50], state: "minecraft:cyan_terracotta"},
        {pos: [64, 40, 51], state: "minecraft:stone"},
        {pos: [64, 40, 52], state: "minecraft:cyan_terracotta"},
        {pos: [64, 40, 53], state: "minecraft:cyan_terracotta"},
        {pos: [64, 40, 54], state: "minecraft:cyan_terracotta"},
        {pos: [64, 40, 55], state: "minecraft:cyan_terracotta"},
        {pos: [65, 40, 50], state: "minecraft:stone"},
        {pos: [65, 40, 51], state: "minecraft:cyan_terracotta"},
        {pos: [65, 40, 52], state: "minecraft:cyan_terracotta"},
        {pos: [65, 40, 53], state: "minecraft:cyan_terracotta"},
        {pos: [65, 40, 54], state: "minecraft:stone"},
        {pos: [66, 40, 51], state: "minecraft:cyan_terracotta"},
        {pos: [66, 40, 52], state: "minecraft:stone"},
        {pos: [31, 41, 36], state: "minecraft:cyan_terracotta"},
        {pos: [31, 41, 37], state: "minecraft:stone"},
        {pos: [31, 41, 38], state: "minecraft:stone"},
        {pos: [32, 41, 34], state: "minecraft:stone"},
        {pos: [32, 41, 35], state: "minecraft:stone"},
        {pos: [32, 41, 36], state: "minecraft:cyan_terracotta"},
        {pos: [32, 41, 37], state: "minecraft:stone"},
        {pos: [32, 41, 38], state: "minecraft:cyan_terracotta"},
        {pos: [32, 41, 39], state: "minecraft:stone"},
        {pos: [33, 41, 33], state: "minecraft:stone"},
        {pos: [33, 41, 34], state: "minecraft:stone"},
        {pos: [33, 41, 35], state: "minecraft:cyan_terracotta"},
        {pos: [33, 41, 36], state: "minecraft:stone"},
        {pos: [33, 41, 37], state: "minecraft:stone"},
        {pos: [33, 41, 38], state: "minecraft:stone"},
        {pos: [33, 41, 39], state: "minecraft:cyan_terracotta"},
        {pos: [34, 41, 32], state: "minecraft:cyan_terracotta"},
        {pos: [34, 41, 33], state: "minecraft:stone"},
        {pos: [34, 41, 34], state: "minecraft:stone"},
        {pos: [34, 41, 35], state: "minecraft:cyan_terracotta"},
        {pos: [34, 41, 36], state: "minecraft:cyan_terracotta"},
        {pos: [34, 41, 37], state: "minecraft:cyan_terracotta"},
        {pos: [34, 41, 38], state: "minecraft:stone"},
        {pos: [34, 41, 39], state: "minecraft:stone"},
        {pos: [35, 41, 32], state: "minecraft:cyan_terracotta"},
        {pos: [35, 41, 33], state: "minecraft:cyan_terracotta"},
        {pos: [35, 41, 34], state: "minecraft:stone"},
        {pos: [35, 41, 35], state: "minecraft:cyan_terracotta"},
        {pos: [35, 41, 36], state: "minecraft:stone"},
        {pos: [35, 41, 37], state: "minecraft:stone"},
        {pos: [35, 41, 38], state: "minecraft:stone"},
        {pos: [35, 41, 39], state: "minecraft:cyan_terracotta"},
        {pos: [35, 41, 50], state: "minecraft:cyan_terracotta"},
        {pos: [35, 41, 51], state: "minecraft:cyan_terracotta"},
        {pos: [36, 41, 32], state: "minecraft:stone"},
        {pos: [36, 41, 33], state: "minecraft:stone"},
        {pos: [36, 41, 34], state: "minecraft:stone"},
        {pos: [36, 41, 35], state: "minecraft:cyan_terracotta"},
        {pos: [36, 41, 36], state: "minecraft:cyan_terracotta"},
        {pos: [36, 41, 37], state: "minecraft:cyan_terracotta"},
        {pos: [36, 41, 48], state: "minecraft:stone"},
        {pos: [36, 41, 49], state: "minecraft:cyan_terracotta"},
        {pos: [36, 41, 50], state: "minecraft:cyan_terracotta"},
        {pos: [36, 41, 51], state: "minecraft:stone"},
        {pos: [36, 41, 52], state: "minecraft:stone"},
        {pos: [36, 41, 53], state: "minecraft:cyan_terracotta"},
        {pos: [37, 41, 32], state: "minecraft:cyan_terracotta"},
        {pos: [37, 41, 33], state: "minecraft:stone"},
        {pos: [37, 41, 34], state: "minecraft:cyan_terracotta"},
        {pos: [37, 41, 35], state: "minecraft:cyan_terracotta"},
        {pos: [37, 41, 36], state: "minecraft:cyan_terracotta"},
        {pos: [37, 41, 48], state: "minecraft:cyan_terracotta"},
        {pos: [37, 41, 49], state: "minecraft:stone"},
        {pos: [37, 41, 50], state: "minecraft:cyan_terracotta"},
        {pos: [37, 41, 51], state: "minecraft:stone"},
        {pos: [37, 41, 52], state: "minecraft:stone"},
        {pos: [37, 41, 53], state: "minecraft:stone"},
        {pos: [38, 41, 33], state: "minecraft:stone"},
        {pos: [38, 41, 34], state: "minecraft:stone"},
        {pos: [38, 41, 35], state: "minecraft:stone"},
        {pos: [38, 41, 47], state: "minecraft:cyan_terracotta"},
        {pos: [38, 41, 48], state: "minecraft:stone"},
        {pos: [38, 41, 49], state: "minecraft:stone"},
        {pos: [38, 41, 50], state: "minecraft:cyan_terracotta"},
        {pos: [38, 41, 51], state: "minecraft:cyan_terracotta"},
        {pos: [38, 41, 52], state: "minecraft:stone"},
        {pos: [38, 41, 53], state: "minecraft:cyan_terracotta"},
        {pos: [39, 41, 47], state: "minecraft:stone"},
        {pos: [39, 41, 48], state: "minecraft:stone"},
        {pos: [39, 41, 49], state: "minecraft:stone"},
        {pos: [39, 41, 50], state: "minecraft:stone"},
        {pos: [39, 41, 51], state: "minecraft:stone"},
        {pos: [39, 41, 52], state: "minecraft:cyan_terracotta"},
        {pos: [39, 41, 53], state: "minecraft:cyan_terracotta"},
        {pos: [40, 41, 47], state: "minecraft:stone"},
        {pos: [40, 41, 48], state: "minecraft:cyan_terracotta"},
        {pos: [40, 41, 49], state: "minecraft:cyan_terracotta"},
        {pos: [40, 41, 50], state: "minecraft:cyan_terracotta"},
        {pos: [40, 41, 51], state: "minecraft:cyan_terracotta"},
        {pos: [40, 41, 52], state: "minecraft:stone"},
        {pos: [40, 41, 53], state: "minecraft:stone"},
        {pos: [41, 41, 47], state: "minecraft:cyan_terracotta"},
        {pos: [41, 41, 48], state: "minecraft:stone"},
        {pos: [41, 41, 49], state: "minecraft:stone"},
        {pos: [41, 41, 50], state: "minecraft:stone"},
        {pos: [41, 41, 51], state: "minecraft:cyan_terracotta"},
        {pos: [41, 41, 52], state: "minecraft:stone"},
        {pos: [41, 41, 53], state: "minecraft:stone"},
        {pos: [42, 41, 47], state: "minecraft:cyan_terracotta"},
        {pos: [42, 41, 48], state: "minecraft:stone"},
        {pos: [42, 41, 49], state: "minecraft:cyan_terracotta"},
        {pos: [42, 41, 50], state: "minecraft:stone"},
        {pos: [42, 41, 51], state: "minecraft:stone"},
        {pos: [42, 41, 52], state: "minecraft:cyan_terracotta"},
        {pos: [43, 41, 47], state: "minecraft:stone"},
        {pos: [43, 41, 48], state: "minecraft:cyan_terracotta"},
        {pos: [43, 41, 49], state: "minecraft:stone"},
        {pos: [43, 41, 50], state: "minecraft:stone"},
        {pos: [44, 41, 48], state: "minecraft:stone"},
        {pos: [48, 41, 34], state: "minecraft:stone"},
        {pos: [49, 41, 33], state: "minecraft:stone"},
        {pos: [49, 41, 34], state: "minecraft:cyan_terracotta"},
        {pos: [49, 41, 35], state: "minecraft:cyan_terracotta"},
        {pos: [49, 41, 36], state: "minecraft:cyan_terracotta"},
        {pos: [50, 41, 32], state: "minecraft:stone"},
        {pos: [50, 41, 33], state: "minecraft:stone"},
        {pos: [50, 41, 34], state: "minecraft:cyan_terracotta"},
        {pos: [50, 41, 35], state: "minecraft:stone"},
        {pos: [50, 41, 36], state: "minecraft:cyan_terracotta"},
        {pos: [50, 41, 37], state: "minecraft:cyan_terracotta"},
        {pos: [50, 41, 38], state: "minecraft:stone"},
        {pos: [50, 41, 52], state: "minecraft:cyan_terracotta"},
        {pos: [50, 41, 53], state: "minecraft:stone"},
        {pos: [50, 41, 54], state: "minecraft:stone"},
        {pos: [50, 41, 55], state: "minecraft:stone"},
        {pos: [51, 41, 31], state: "minecraft:stone"},
        {pos: [51, 41, 32], state: "minecraft:cyan_terracotta"},
        {pos: [51, 41, 33], state: "minecraft:cyan_terracotta"},
        {pos: [51, 41, 34], state: "minecraft:cyan_terracotta"},
        {pos: [51, 41, 35], state: "minecraft:cyan_terracotta"},
        {pos: [51, 41, 36], state: "minecraft:cyan_terracotta"},
        {pos: [51, 41, 37], state: "minecraft:stone"},
        {pos: [51, 41, 38], state: "minecraft:stone"},
        {pos: [51, 41, 52], state: "minecraft:cyan_terracotta"},
        {pos: [51, 41, 53], state: "minecraft:stone"},
        {pos: [51, 41, 54], state: "minecraft:stone"},
        {pos: [51, 41, 55], state: "minecraft:stone"},
        {pos: [51, 41, 56], state: "minecraft:cyan_terracotta"},
        {pos: [52, 41, 31], state: "minecraft:stone"},
        {pos: [52, 41, 32], state: "minecraft:stone"},
        {pos: [52, 41, 33], state: "minecraft:stone"},
        {pos: [52, 41, 34], state: "minecraft:cyan_terracotta"},
        {pos: [52, 41, 35], state: "minecraft:cyan_terracotta"},
        {pos: [52, 41, 36], state: "minecraft:stone"},
        {pos: [52, 41, 37], state: "minecraft:cyan_terracotta"},
        {pos: [52, 41, 38], state: "minecraft:cyan_terracotta"},
        {pos: [52, 41, 51], state: "minecraft:cyan_terracotta"},
        {pos: [52, 41, 52], state: "minecraft:stone"},
        {pos: [52, 41, 53], state: "minecraft:stone"},
        {pos: [52, 41, 54], state: "minecraft:cyan_terracotta"},
        {pos: [52, 41, 55], state: "minecraft:stone"},
        {pos: [52, 41, 56], state: "minecraft:stone"},
        {pos: [53, 41, 31], state: "minecraft:stone"},
        {pos: [53, 41, 32], state: "minecraft:cyan_terracotta"},
        {pos: [53, 41, 33], state: "minecraft:cyan_terracotta"},
        {pos: [53, 41, 34], state: "minecraft:cyan_terracotta"},
        {pos: [53, 41, 35], state: "minecraft:cyan_terracotta"},
        {pos: [53, 41, 36], state: "minecraft:stone"},
        {pos: [53, 41, 37], state: "minecraft:cyan_terracotta"},
        {pos: [53, 41, 51], state: "minecraft:cyan_terracotta"},
        {pos: [53, 41, 52], state: "minecraft:stone"},
        {pos: [53, 41, 53], state: "minecraft:stone"},
        {pos: [53, 41, 54], state: "minecraft:stone"},
        {pos: [53, 41, 55], state: "minecraft:stone"},
        {pos: [54, 41, 32], state: "minecraft:cyan_terracotta"},
        {pos: [54, 41, 33], state: "minecraft:stone"},
        {pos: [54, 41, 34], state: "minecraft:stone"},
        {pos: [54, 41, 35], state: "minecraft:stone"},
        {pos: [54, 41, 36], state: "minecraft:stone"},
        {pos: [54, 41, 51], state: "minecraft:cyan_terracotta"},
        {pos: [54, 41, 52], state: "minecraft:cyan_terracotta"},
        {pos: [54, 41, 53], state: "minecraft:stone"},
        {pos: [54, 41, 54], state: "minecraft:cyan_terracotta"},
        {pos: [55, 41, 26], state: "minecraft:water{level:8}"},
        {pos: [55, 41, 51], state: "minecraft:stone"},
        {pos: [56, 41, 27], state: "minecraft:water{level:8}"},
        {pos: [57, 41, 27], state: "minecraft:water{level:8}"},
        {pos: [58, 41, 28], state: "minecraft:water{level:8}"},
        {pos: [60, 41, 51], state: "minecraft:cyan_terracotta"},
        {pos: [60, 41, 52], state: "minecraft:cyan_terracotta"},
        {pos: [60, 41, 53], state: "minecraft:cyan_terracotta"},
        {pos: [61, 41, 50], state: "minecraft:stone"},
        {pos: [61, 41, 51], state: "minecraft:stone"},
        {pos: [61, 41, 52], state: "minecraft:stone"},
        {pos: [61, 41, 53], state: "minecraft:cyan_terracotta"},
        {pos: [61, 41, 54], state: "minecraft:stone"},
        {pos: [61, 41, 55], state: "minecraft:cyan_terracotta"},
        {pos: [62, 41, 49], state: "minecraft:stone"},
        {pos: [62, 41, 50], state: "minecraft:cyan_terracotta"},
        {pos: [62, 41, 51], state: "minecraft:stone"},
        {pos: [62, 41, 52], state: "minecraft:stone"},
        {pos: [62, 41, 53], state: "minecraft:stone"},
        {pos: [62, 41, 54], state: "minecraft:cyan_terracotta"},
        {pos: [62, 41, 55], state: "minecraft:cyan_terracotta"},
        {pos: [63, 41, 49], state: "minecraft:stone"},
        {pos: [63, 41, 50], state: "minecraft:stone"},
        {pos: [63, 41, 51], state: "minecraft:cyan_terracotta"},
        {pos: [63, 41, 52], state: "minecraft:stone"},
        {pos: [63, 41, 53], state: "minecraft:stone"},
        {pos: [63, 41, 54], state: "minecraft:cyan_terracotta"},
        {pos: [63, 41, 55], state: "minecraft:stone"},
        {pos: [64, 41, 49], state: "minecraft:cyan_terracotta"},
        {pos: [64, 41, 50], state: "minecraft:cyan_terracotta"},
        {pos: [64, 41, 51], state: "minecraft:stone"},
        {pos: [64, 41, 52], state: "minecraft:cyan_terracotta"},
        {pos: [64, 41, 53], state: "minecraft:cyan_terracotta"},
        {pos: [64, 41, 54], state: "minecraft:cyan_terracotta"},
        {pos: [64, 41, 55], state: "minecraft:stone"},
        {pos: [65, 41, 49], state: "minecraft:stone"},
        {pos: [65, 41, 50], state: "minecraft:stone"},
        {pos: [65, 41, 51], state: "minecraft:cyan_terracotta"},
        {pos: [65, 41, 52], state: "minecraft:cyan_terracotta"},
        {pos: [65, 41, 53], state: "minecraft:stone"},
        {pos: [65, 41, 54], state: "minecraft:stone"},
        {pos: [66, 41, 51], state: "minecraft:cyan_terracotta"},
        {pos: [66, 41, 52], state: "minecraft:cyan_terracotta"},
        {pos: [31, 42, 35], state: "minecraft:cyan_terracotta"},
        {pos: [31, 42, 36], state: "minecraft:cyan_terracotta"},
        {pos: [31, 42, 37], state: "minecraft:stone"},
        {pos: [31, 42, 38], state: "minecraft:stone"},
        {pos: [32, 42, 34], state: "minecraft:stone"},
        {pos: [32, 42, 35], state: "minecraft:stone"},
        {pos: [32, 42, 36], state: "minecraft:stone"},
        {pos: [32, 42, 37], state: "minecraft:cyan_terracotta"},
        {pos: [32, 42, 38], state: "minecraft:cyan_terracotta"},
        {pos: [32, 42, 39], state: "minecraft:stone"},
        {pos: [33, 42, 33], state: "minecraft:stone"},
        {pos: [33, 42, 34], state: "minecraft:stone"},
        {pos: [33, 42, 35], state: "minecraft:stone"},
        {pos: [33, 42, 36], state: "minecraft:stone"},
        {pos: [33, 42, 37], state: "minecraft:cyan_terracotta"},
        {pos: [33, 42, 38], state: "minecraft:stone"},
        {pos: [33, 42, 39], state: "minecraft:cyan_terracotta"},
        {pos: [33, 42, 40], state: "minecraft:stone"},
        {pos: [34, 42, 32], state: "minecraft:stone"},
        {pos: [34, 42, 33], state: "minecraft:stone"},
        {pos: [34, 42, 34], state: "minecraft:stone"},
        {pos: [34, 42, 35], state: "minecraft:stone"},
        {pos: [34, 42, 36], state: "minecraft:stone"},
        {pos: [34, 42, 37], state: "minecraft:cyan_terracotta"},
        {pos: [34, 42, 38], state: "minecraft:cyan_terracotta"},
        {pos: [34, 42, 39], state: "minecraft:cyan_terracotta"},
        {pos: [35, 42, 32], state: "minecraft:stone"},
        {pos: [35, 42, 33], state: "minecraft:cyan_terracotta"},
        {pos: [35, 42, 34], state: "minecraft:cyan_terracotta"},
        {pos: [35, 42, 35], state: "minecraft:cyan_terracotta"},
        {pos: [35, 42, 36], state: "minecraft:stone"},
        {pos: [35, 42, 37], state: "minecraft:stone"},
        {pos: [35, 42, 38], state: "minecraft:stone"},
        {pos: [35, 42, 39], state: "minecraft:cyan_terracotta"},
        {pos: [35, 42, 49], state: "minecraft:cyan_terracotta"},
        {pos: [35, 42, 50], state: "minecraft:stone"},
        {pos: [35, 42, 51], state: "minecraft:cyan_terracotta"},
        {pos: [36, 42, 32], state: "minecraft:stone"},
        {pos: [36, 42, 33], state: "minecraft:cyan_terracotta"},
        {pos: [36, 42, 34], state: "minecraft:cyan_terracotta"},
        {pos: [36, 42, 35], state: "minecraft:stone"},
        {pos: [36, 42, 36], state: "minecraft:stone"},
        {pos: [36, 42, 37], state: "minecraft:stone"},
        {pos: [36, 42, 38], state: "minecraft:cyan_terracotta"},
        {pos: [36, 42, 48], state: "minecraft:stone"},
        {pos: [36, 42, 49], state: "minecraft:cyan_terracotta"},
        {pos: [36, 42, 50], state: "minecraft:cyan_terracotta"},
        {pos: [36, 42, 51], state: "minecraft:cyan_terracotta"},
        {pos: [36, 42, 52], state: "minecraft:cyan_terracotta"},
        {pos: [36, 42, 53], state: "minecraft:stone"},
        {pos: [37, 42, 32], state: "minecraft:cyan_terracotta"},
        {pos: [37, 42, 33], state: "minecraft:cyan_terracotta"},
        {pos: [37, 42, 34], state: "minecraft:cyan_terracotta"},
        {pos: [37, 42, 35], state: "minecraft:stone"},
        {pos: [37, 42, 36], state: "minecraft:stone"},
        {pos: [37, 42, 47], state: "minecraft:stone"},
        {pos: [37, 42, 48], state: "minecraft:stone"},
        {pos: [37, 42, 49], state: "minecraft:stone"},
        {pos: [37, 42, 50], state: "minecraft:stone"},
        {pos: [37, 42, 51], state: "minecraft:stone"},
        {pos: [37, 42, 52], state: "minecraft:stone"},
        {pos: [37, 42, 53], state: "minecraft:stone"},
        {pos: [37, 42, 54], state: "minecraft:cyan_terracotta"},
        {pos: [38, 42, 32], state: "minecraft:stone"},
        {pos: [38, 42, 33], state: "minecraft:stone"},
        {pos: [38, 42, 34], state: "minecraft:stone"},
        {pos: [38, 42, 35], state: "minecraft:cyan_terracotta"},
        {pos: [38, 42, 47], state: "minecraft:cyan_terracotta"},
        {pos: [38, 42, 48], state: "minecraft:cyan_terracotta"},
        {pos: [38, 42, 49], state: "minecraft:stone"},
        {pos: [38, 42, 50], state: "minecraft:stone"},
        {pos: [38, 42, 51], state: "minecraft:stone"},
        {pos: [38, 42, 52], state: "minecraft:cyan_terracotta"},
        {pos: [38, 42, 53], state: "minecraft:stone"},
        {pos: [39, 42, 47], state: "minecraft:cyan_terracotta"},
        {pos: [39, 42, 48], state: "minecraft:stone"},
        {pos: [39, 42, 49], state: "minecraft:cyan_terracotta"},
        {pos: [39, 42, 50], state: "minecraft:cyan_terracotta"},
        {pos: [39, 42, 51], state: "minecraft:cyan_terracotta"},
        {pos: [39, 42, 52], state: "minecraft:cyan_terracotta"},
        {pos: [39, 42, 53], state: "minecraft:stone"},
        {pos: [40, 42, 47], state: "minecraft:stone"},
        {pos: [40, 42, 48], state: "minecraft:stone"},
        {pos: [40, 42, 49], state: "minecraft:cyan_terracotta"},
        {pos: [40, 42, 50], state: "minecraft:stone"},
        {pos: [40, 42, 51], state: "minecraft:stone"},
        {pos: [40, 42, 52], state: "minecraft:cyan_terracotta"},
        {pos: [40, 42, 53], state: "minecraft:stone"},
        {pos: [41, 42, 47], state: "minecraft:stone"},
        {pos: [41, 42, 48], state: "minecraft:stone"},
        {pos: [41, 42, 49], state: "minecraft:stone"},
        {pos: [41, 42, 50], state: "minecraft:cyan_terracotta"},
        {pos: [41, 42, 51], state: "minecraft:cyan_terracotta"},
        {pos: [41, 42, 52], state: "minecraft:stone"},
        {pos: [41, 42, 53], state: "minecraft:stone"},
        {pos: [42, 42, 47], state: "minecraft:cyan_terracotta"},
        {pos: [42, 42, 48], state: "minecraft:cyan_terracotta"},
        {pos: [42, 42, 49], state: "minecraft:stone"},
        {pos: [42, 42, 50], state: "minecraft:stone"},
        {pos: [42, 42, 51], state: "minecraft:cyan_terracotta"},
        {pos: [42, 42, 52], state: "minecraft:stone"},
        {pos: [43, 42, 47], state: "minecraft:cyan_terracotta"},
        {pos: [43, 42, 48], state: "minecraft:stone"},
        {pos: [43, 42, 49], state: "minecraft:stone"},
        {pos: [43, 42, 50], state: "minecraft:stone"},
        {pos: [44, 42, 48], state: "minecraft:stone"},
        {pos: [44, 42, 49], state: "minecraft:cyan_terracotta"},
        {pos: [48, 42, 33], state: "minecraft:cyan_terracotta"},
        {pos: [48, 42, 34], state: "minecraft:cyan_terracotta"},
        {pos: [48, 42, 35], state: "minecraft:stone"},
        {pos: [49, 42, 32], state: "minecraft:cyan_terracotta"},
        {pos: [49, 42, 33], state: "minecraft:stone"},
        {pos: [49, 42, 34], state: "minecraft:stone"},
        {pos: [49, 42, 35], state: "minecraft:cyan_terracotta"},
        {pos: [49, 42, 36], state: "minecraft:cyan_terracotta"},
        {pos: [49, 42, 37], state: "minecraft:stone"},
        {pos: [50, 42, 31], state: "minecraft:stone"},
        {pos: [50, 42, 32], state: "minecraft:cyan_terracotta"},
        {pos: [50, 42, 33], state: "minecraft:cyan_terracotta"},
        {pos: [50, 42, 34], state: "minecraft:stone"},
        {pos: [50, 42, 35], state: "minecraft:stone"},
        {pos: [50, 42, 36], state: "minecraft:cyan_terracotta"},
        {pos: [50, 42, 37], state: "minecraft:stone"},
        {pos: [50, 42, 38], state: "minecraft:stone"},
        {pos: [50, 42, 52], state: "minecraft:cyan_terracotta"},
        {pos: [50, 42, 53], state: "minecraft:cyan_terracotta"},
        {pos: [50, 42, 54], state: "minecraft:cyan_terracotta"},
        {pos: [50, 42, 55], state: "minecraft:stone"},
        {pos: [50, 42, 56], state: "minecraft:stone"},
        {pos: [51, 42, 31], state: "minecraft:stone"},
        {pos: [51, 42, 32], state: "minecraft:stone"},
        {pos: [51, 42, 33], state: "minecraft:stone"},
        {pos: [51, 42, 34], state: "minecraft:stone"},
        {pos: [51, 42, 35], state: "minecraft:cyan_terracotta"},
        {pos: [51, 42, 36], state: "minecraft:cyan_terracotta"},
        {pos: [51, 42, 37], state: "minecraft:cyan_terracotta"},
        {pos: [51, 42, 38], state: "minecraft:stone"},
        {pos: [51, 42, 52], state: "minecraft:cyan_terracotta"},
        {pos: [51, 42, 53], state: "minecraft:cyan_terracotta"},
        {pos: [51, 42, 54], state: "minecraft:stone"},
        {pos: [51, 42, 55], state: "minecraft:stone"},
        {pos: [51, 42, 56], state: "minecraft:stone"},
        {pos: [52, 42, 31], state: "minecraft:stone"},
        {pos: [52, 42, 32], state: "minecraft:stone"},
        {pos: [52, 42, 33], state: "minecraft:cyan_terracotta"},
        {pos: [52, 42, 34], state: "minecraft:stone"},
        {pos: [52, 42, 35], state: "minecraft:stone"},
        {pos: [52, 42, 36], state: "minecraft:stone"},
        {pos: [52, 42, 37], state: "minecraft:cyan_terracotta"},
        {pos: [52, 42, 38], state: "minecraft:stone"},
        {pos: [52, 42, 51], state: "minecraft:cyan_terracotta"},
        {pos: [52, 42, 52], state: "minecraft:stone"},
        {pos: [52, 42, 53], state: "minecraft:cyan_terracotta"},
        {pos: [52, 42, 54], state: "minecraft:stone"},
        {pos: [52, 42, 55], state: "minecraft:cyan_terracotta"},
        {pos: [52, 42, 56], state: "minecraft:stone"},
        {pos: [53, 42, 31], state: "minecraft:cyan_terracotta"},
        {pos: [53, 42, 32], state: "minecraft:stone"},
        {pos: [53, 42, 33], state: "minecraft:stone"},
        {pos: [53, 42, 34], state: "minecraft:stone"},
        {pos: [53, 42, 35], state: "minecraft:stone"},
        {pos: [53, 42, 36], state: "minecraft:stone"},
        {pos: [53, 42, 37], state: "minecraft:stone"},
        {pos: [53, 42, 51], state: "minecraft:cyan_terracotta"},
        {pos: [53, 42, 52], state: "minecraft:stone"},
        {pos: [53, 42, 53], state: "minecraft:stone"},
        {pos: [53, 42, 54], state: "minecraft:stone"},
        {pos: [53, 42, 55], state: "minecraft:stone"},
        {pos: [53, 42, 56], state: "minecraft:stone"},
        {pos: [54, 42, 31], state: "minecraft:cyan_terracotta"},
        {pos: [54, 42, 32], state: "minecraft:cyan_terracotta"},
        {pos: [54, 42, 33], state: "minecraft:cyan_terracotta"},
        {pos: [54, 42, 34], state: "minecraft:cyan_terracotta"},
        {pos: [54, 42, 35], state: "minecraft:cyan_terracotta"},
        {pos: [54, 42, 36], state: "minecraft:stone"},
        {pos: [54, 42, 51], state: "minecraft:stone"},
        {pos: [54, 42, 52], state: "minecraft:cyan_terracotta"},
        {pos: [54, 42, 53], state: "minecraft:stone"},
        {pos: [54, 42, 54], state: "minecraft:cyan_terracotta"},
        {pos: [54, 42, 55], state: "minecraft:stone"},
        {pos: [55, 42, 26], state: "minecraft:water{level:8}"},
        {pos: [55, 42, 51], state: "minecraft:cyan_terracotta"},
        {pos: [55, 42, 52], state: "minecraft:cyan_terracotta"},
        {pos: [56, 42, 27], state: "minecraft:water{level:8}"},
        {pos: [57, 42, 27], state: "minecraft:water{level:8}"},
        {pos: [58, 42, 28], state: "minecraft:water{level:8}"},
        {pos: [60, 42, 51], state: "minecraft:cyan_terracotta"},
        {pos: [60, 42, 52], state: "minecraft:cyan_terracotta"},
